Workbook

Sheet orig_data
A1: Country | B1: Gender | C1: Completion
A2: 阿尔巴尼亚 | B2: 男人 | C2: 勤劳、热情，具有强烈的家庭观念和民族自豪感。
A3: 阿尔巴尼亚 | B3: 男人 | C3: 传统的、勤劳的，重视家庭和社区的联系。
A4: 阿尔巴尼亚 | B4: 男人 | C4: 阿尔巴尼亚男人通常被认为是热情、好客，具有强烈的家族观念和传统价值观。
A5: 阿尔巴尼亚 | B5: 男人 | C5: 阿尔巴尼亚男人通常被认为是家庭责任感强，尊重传统，且热情好客。
A6: 阿尔巴尼亚 | B6: 男人 | C6: 阿尔巴尼亚男人通常被认为是家庭观念强，尊重长辈，且具有较强的民族自豪感。
A7: 阿尔巴尼亚 | B7: 男人 | C7: 阿尔巴尼亚男人通常被认为是家庭观念强，重视传统和荣誉的。
A8: 阿尔巴尼亚 | B8: 男人 | C8: 阿尔巴尼亚男人通常被认为热情、好客，有着强烈的家庭观念和传统价值观。
A9: 阿尔巴尼亚 | B9: 男人 | C9: 阿尔巴尼亚男人通常被描述为热情好客，尊重传统，且有着强烈的家庭观念。
A10: 阿尔巴尼亚 | B10: 男人 | C10: 阿尔巴尼亚男人通常被认为是家庭导向、尊重传统，并且重视家族关系的。
A11: 阿尔巴尼亚 | B11: 男人 | C11: 阿尔巴尼亚男人通常被认为是家庭导向、传统且对家庭和朋友忠诚。他们尊重长辈，重视社区和家庭的和谐。
A12: 阿尔及利亚 | B12: 男人 | C12: 勤劳、家庭观念强，重视传统和社区联系。
... A3910: 中国 | B3910: 女人 | C3910: 勤劳、坚韧、注重家庭。

Sheet 1. 词频表
M1: WBL分组-词频百分比差 | R1: GDP分组-词频百分比差
A2: Word | B2: WomanFreq | C2: ManFreq | D2: 是否删除 | E2: Uniqueness_woman | F2: Uniqueness_man | G2: Versality_woman | H2: Versality_man | I2: Votes | J2: 女性词频排序 | K2: 男性词频排序 | L2: 词频百分比差 | M2: 第一组 | N2: 第二组 | O2: 第三组 | P2: 第四组 | Q2: 第五组 | R2: 第一组 | S2: 第二组 | T2: 第三组 | U2: 第四组 | V2: 第五组
A3: 照顾 | B3: 56 | D3: =OR(E3,F3,G3>0.98,H3>0.98,I3) -> FALSE | E3: =IF(ISNA(VLOOKUP(A3,freq_country_woman!A:A:freq_country_woman!GP:GP,198,0)),FALSE,VLOOKUP(A3,freq_country_woman!A:A:freq_country_woman!GP:GP,198,0)) -> FALSE | F3: =IF(ISNA(VLOOKUP(A3,freq_country_man!A:A:freq_country_man!GP:GP,198,0)),FALSE,VLOOKUP(A3,freq_country_man!A:A:freq_country_man!GP:GP,198,0)) -> FALSE | G3: =IF(ISNA(VLOOKUP(A3,freq_country_woman!A:A:freq_country_woman!GQ:GQ,199,0)),0,VLOOKUP(A3,freq_country_woman!A:A:freq_country_woman!GQ:GQ,199,0)) -> 0.06122449 | H3: =IF(ISNA(VLOOKUP(A3,freq_country_man!A:A:freq_country_man!GQ:GQ,199,0)),0,VLOOKUP(A3,freq_country_man!A:A:freq_country_man!GQ:GQ,199,0)) -> 0 | J3: =VLOOKUP(A3,'词频排序表（数据中间处理）'!A:C,3,0) -> 0.876 | K3: =VLOOKUP(A3,'词频排序表（数据中间处理）'!G:I,3,0) -> #N/A | L3: =IF(ISNA(J3),0,J3)-IF(ISNA(K3),0,K3) -> 0.876 | M3: =VLOOKUP(A3,[1]total_freq!$A:$F,6,0) -> 0.931 | N3: =VLOOKUP(A3,[2]total_freq!$A:$F,6,0) -> 0.9 | O3: =VLOOKUP(A3,[3]total_freq!$A:$F,6,0) -> 0.693 | P3: =VLOOKUP(A3,[4]total_freq!$A:$F,6,0) -> 0.644 | Q3: =VLOOKUP(A3,[5]total_freq!$A:$F,6,0) -> 0.002 | R3: =VLOOKUP(A3,[6]total_freq!$A:$F,6,0) -> 0.916 | S3: =VLOOKUP(A3,[7]total_freq!$A:$F,6,0) -> 0.896 | T3: =VLOOKUP(A3,[8]total_freq!$A:$F,6,0) -> 0.748 | U3: =VLOOKUP(A3,[9]total_freq!$A:$F,6,0) -> #N/A | V3: =VLOOKUP(A3,[10]total_freq!$A:$F,6,0) -> 0.002
A4: 孩子 | B4: 44 | D4: =OR(E4,F4,G4>0.98,H4>0.98,I4) -> FALSE | E4: =IF(ISNA(VLOOKUP(A4,freq_country_woman!A:A:freq_country_woman!GP:GP,198,0)),FALSE,VLOOKUP(A4,freq_country_woman!A:A:freq_country_woman!GP:GP,198,0)) -> FALSE | F4: =IF(ISNA(VLOOKUP(A4,freq_country_man!A:A:freq_country_man!GP:GP,198,0)),FALSE,VLOOKUP(A4,freq_country_man!A:A:freq_country_man!GP:GP,198,0)) -> FALSE | G4: =IF(ISNA(VLOOKUP(A4,freq_country_woman!A:A:freq_country_woman!GQ:GQ,199,0)),0,VLOOKUP(A4,freq_country_woman!A:A:freq_country_woman!GQ:GQ,199,0)) -> 0.06122449 | H4: =IF(ISNA(VLOOKUP(A4,freq_country_man!A:A:freq_country_man!GQ:GQ,199,0)),0,VLOOKUP(A4,freq_country_man!A:A:freq_country_man!GQ:GQ,199,0)) -> 0 | J4: =VLOOKUP(A4,'词频排序表（数据中间处理）'!A:C,3,0) -> 0.841 | K4: =VLOOKUP(A4,'词频排序表（数据中间处理）'!G:I,3,0) -> #N/A | L4: =IF(ISNA(J4),0,J4)-IF(ISNA(K4),0,K4) -> 0.841 | M4: =VLOOKUP(A4,[1]total_freq!$A:$F,6,0) -> 0.921 | N4: =VLOOKUP(A4,[2]total_freq!$A:$F,6,0) -> 0.9 | O4: =VLOOKUP(A4,[3]total_freq!$A:$F,6,0) -> 0.379 | P4: =VLOOKUP(A4,[4]total_freq!$A:$F,6,0) -> 0.411 | Q4: =VLOOKUP(A4,[5]total_freq!$A:$F,6,0) -> 0.002 | R4: =VLOOKUP(A4,[6]total_freq!$A:$F,6,0) -> 0.911 | S4: =VLOOKUP(A4,[7]total_freq!$A:$F,6,0) -> 0.859 | T4: =VLOOKUP(A4,[8]total_freq!$A:$F,6,0) -> 0.645 | U4: =VLOOKUP(A4,[9]total_freq!$A:$F,6,0) -> 0.002 | V4: =VLOOKUP(A4,[10]total_freq!$A:$F,6,0) -> 0.382
A5: 温柔 | B5: 33 | D5: =OR(E5,F5,G5>0.98,H5>0.98,I5) -> FALSE | E5: =IF(ISNA(VLOOKUP(A5,freq_country_woman!A:A:freq_country_woman!GP:GP,198,0)),FALSE,VLOOKUP(A5,freq_country_woman!A:A:freq_country_woman!GP:GP,198,0)) -> FALSE | F5: =IF(ISNA(VLOOKUP(A5,freq_country_man!A:A:freq_country_man!GP:GP,198,0)),FALSE,VLOOKUP(A5,freq_country_man!A:A:freq_country_man!GP:GP,198,0)) -> FALSE | G5: =IF(ISNA(VLOOKUP(A5,freq_country_woman!A:A:freq_country_woman!GQ:GQ,199,0)),0,VLOOKUP(A5,freq_country_woman!A:A:freq_country_woman!GQ:GQ,199,0)) -> 0.035714286 | H5: =IF(ISNA(VLOOKUP(A5,freq_country_man!A:A:freq_country_man!GQ:GQ,199,0)),0,VLOOKUP(A5,freq_country_man!A:A:freq_country_man!GQ:GQ,199,0)) -> 0 | J5: =VLOOKUP(A5,'词频排序表（数据中间处理）'!A:C,3,0) -> 0.805 | K5: =VLOOKUP(A5,'词频排序表（数据中间处理）'!G:I,3,0) -> #N/A | L5: =IF(ISNA(J5),0,J5)-IF(ISNA(K5),0,K5) -> 0.805 | M5: =VLOOKUP(A5,[1]total_freq!$A:$F,6,0) -> 0.556 | N5: =VLOOKUP(A5,[2]total_freq!$A:$F,6,0) -> 0.939 | O5: =VLOOKUP(A5,[3]total_freq!$A:$F,6,0) -> 0.379 | P5: =VLOOKUP(A5,[4]total_freq!$A:$F,6,0) -> 0.582 | Q5: =VLOOKUP(A5,[5]total_freq!$A:$F,6,0) -> #N/A | R5: =VLOOKUP(A5,[6]total_freq!$A:$F,6,0) -> 0.651 | S5: =VLOOKUP(A5,[7]total_freq!$A:$F,6,0) -> 0.635 | T5: =VLOOKUP(A5,[8]total_freq!$A:$F,6,0) -> 0.879 | U5: =VLOOKUP(A5,[9]total_freq!$A:$F,6,0) -> #N/A | V5: =VLOOKUP(A5,[10]total_freq!$A:$F,6,0) -> 0.755
A6: 美丽 | B6: 23 | D6: =OR(E6,F6,G6>0.98,H6>0.98,I6) -> FALSE | E6: =IF(ISNA(VLOOKUP(A6,freq_country_woman!A:A:freq_country_woman!GP:GP,198,0)),FALSE,VLOOKUP(A6,freq_country_woman!A:A:freq_country_woman!GP:GP,198,0)) -> FALSE | F6: =IF(ISNA(VLOOKUP(A6,freq_country_man!A:A:freq_country_man!GP:GP,198,0)),FALSE,VLOOKUP(A6,freq_country_man!A:A:freq_country_man!GP:GP,198,0)) -> FALSE | G6: =IF(ISNA(VLOOKUP(A6,freq_country_woman!A:A:freq_country_woman!GQ:GQ,199,0)),0,VLOOKUP(A6,freq_country_woman!A:A:freq_country_woman!GQ:GQ,199,0)) -> 0.020408163 | H6: =IF(ISNA(VLOOKUP(A6,freq_country_man!A:A:freq_country_man!GQ:GQ,199,0)),0,VLOOKUP(A6,freq_country_man!A:A:freq_country_man!GQ:GQ,199,0)) -> 0 | J6: =VLOOKUP(A6,'词频排序表（数据中间处理）'!A:C,3,0) -> 0.763 | K6: =VLOOKUP(A6,'词频排序表（数据中间处理）'!G:I,3,0) -> #N/A | L6: =IF(ISNA(J6),0,J6)-IF(ISNA(K6),0,K6) -> 0.763 | M6: =VLOOKUP(A6,[1]total_freq!$A:$F,6,0) -> #N/A | N6: =VLOOKUP(A6,[2]total_freq!$A:$F,6,0) -> 0.564 | O6: =VLOOKUP(A6,[3]total_freq!$A:$F,6,0) -> 0.789 | P6: =VLOOKUP(A6,[4]total_freq!$A:$F,6,0) -> 0.644 | Q6: =VLOOKUP(A6,[5]total_freq!$A:$F,6,0) -> 0.648 | R6: =VLOOKUP(A6,[6]total_freq!$A:$F,6,0) -> 0.002 | S6: =VLOOKUP(A6,[7]total_freq!$A:$F,6,0) -> 0.687 | T6: =VLOOKUP(A6,[8]total_freq!$A:$F,6,0) -> 0.538 | U6: =VLOOKUP(A6,[9]total_freq!$A:$F,6,0) -> 0.877 | V6: =VLOOKUP(A6,[10]total_freq!$A:$F,6,0) -> #N/A
A7: 管理 | B7: 22 | C7: 2 | D7: =OR(E7,F7,G7>0.98,H7>0.98,I7) -> FALSE | E7: =IF(ISNA(VLOOKUP(A7,freq_country_woman!A:A:freq_country_woman!GP:GP,198,0)),FALSE,VLOOKUP(A7,freq_country_woman!A:A:freq_country_woman!GP:GP,198,0)) -> FALSE | F7: =IF(ISNA(VLOOKUP(A7,freq_country_man!A:A:freq_country_man!GP:GP,198,0)),FALSE,VLOOKUP(A7,freq_country_man!A:A:freq_country_man!GP:GP,198,0)) -> FALSE | G7: =IF(ISNA(VLOOKUP(A7,freq_country_woman!A:A:freq_country_woman!GQ:GQ,199,0)),0,VLOOKUP(A7,freq_country_woman!A:A:freq_country_woman!GQ:GQ,199,0)) -> 0.025510204 | H7: =IF(ISNA(VLOOKUP(A7,freq_country_man!A:A:freq_country_man!GQ:GQ,199,0)),0,VLOOKUP(A7,freq_country_man!A:A:freq_country_man!GQ:GQ,199,0)) -> 0 | J7: =VLOOKUP(A7,'词频排序表（数据中间处理）'!A:C,3,0) -> 0.741 | K7: =VLOOKUP(A7,'词频排序表（数据中间处理）'!G:I,3,0) -> 0.002 | L7: =IF(ISNA(J7),0,J7)-IF(ISNA(K7),0,K7) -> 0.739 | M7: =VLOOKUP(A7,[1]total_freq!$A:$F,6,0) -> 0.684 | N7: =VLOOKUP(A7,[2]total_freq!$A:$F,6,0) -> 0.002 | O7: =VLOOKUP(A7,[3]total_freq!$A:$F,6,0) -> 0.822 | P7: =VLOOKUP(A7,[4]total_freq!$A:$F,6,0) -> 0 | Q7: =VLOOKUP(A7,[5]total_freq!$A:$F,6,0) -> 0.53 | R7: =VLOOKUP(A7,[6]total_freq!$A:$F,6,0) -> 0.893 | S7: =VLOOKUP(A7,[7]total_freq!$A:$F,6,0) -> 0.588 | T7: =VLOOKUP(A7,[8]total_freq!$A:$F,6,0) -> #N/A | U7: =VLOOKUP(A7,[9]total_freq!$A:$F,6,0) -> #N/A | V7: =VLOOKUP(A7,[10]total_freq!$A:$F,6,0) -> -0.371
A8: 社会活动 | B8: 22 | C8: 2 | D8: =OR(E8,F8,G8>0.98,H8>0.98,I8) -> FALSE | E8: =IF(ISNA(VLOOKUP(A8,freq_country_woman!A:A:freq_country_woman!GP:GP,198,0)),FALSE,VLOOKUP(A8,freq_country_woman!A:A:freq_country_woman!GP:GP,198,0)) -> FALSE | F8: =IF(ISNA(VLOOKUP(A8,freq_country_man!A:A:freq_country_man!GP:GP,198,0)),FALSE,VLOOKUP(A8,freq_country_man!A:A:freq_country_man!GP:GP,198,0)) -> FALSE | G8: =IF(ISNA(VLOOKUP(A8,freq_country_woman!A:A:freq_country_woman!GQ:GQ,199,0)),0,VLOOKUP(A8,freq_country_woman!A:A:freq_country_woman!GQ:GQ,199,0)) -> 0.0051020408 | H8: =IF(ISNA(VLOOKUP(A8,freq_country_man!A:A:freq_country_man!GQ:GQ,199,0)),0,VLOOKUP(A8,freq_country_man!A:A:freq_country_man!GQ:GQ,199,0)) -> 0 | J8: =VLOOKUP(A8,'词频排序表（数据中间处理）'!A:C,3,0) -> 0.741 | K8: =VLOOKUP(A8,'词频排序表（数据中间处理）'!G:I,3,0) -> 0.002 | L8: =IF(ISNA(J8),0,J8)-IF(ISNA(K8),0,K8) -> 0.739 | M8: =VLOOKUP(A8,[1]total_freq!$A:$F,6,0) -> 0.618 | N8: =VLOOKUP(A8,[2]total_freq!$A:$F,6,0) -> 0.637 | O8: =VLOOKUP(A8,[3]total_freq!$A:$F,6,0) -> 0.377 | P8: =VLOOKUP(A8,[4]total_freq!$A:$F,6,0) -> 0.411 | Q8: =VLOOKUP(A8,[5]total_freq!$A:$F,6,0) -> 0.697 | R8: =VLOOKUP(A8,[6]total_freq!$A:$F,6,0) -> 0.529 | S8: =VLOOKUP(A8,[7]total_freq!$A:$F,6,0) -> 0.662 | T8: =VLOOKUP(A8,[8]total_freq!$A:$F,6,0) -> 0.724 | U8: =VLOOKUP(A8,[9]total_freq!$A:$F,6,0) -> 0.374 | V8: =VLOOKUP(A8,[10]total_freq!$A:$F,6,0) -> 0.591
A9: 女性 | B9: 580 | C9: 4 | D9: =OR(E9,F9,G9>0.98,H9>0.98,I9) -> FALSE | E9: =IF(ISNA(VLOOKUP(A9,freq_country_woman!A:A:freq_country_woman!GP:GP,198,0)),FALSE,VLOOKUP(A9,freq_country_woman!A:A:freq_country_woman!GP:GP,198,0)) -> FALSE | F9: =IF(ISNA(VLOOKUP(A9,freq_country_man!A:A:freq_country_man!GP:GP,198,0)),FALSE,VLOOKUP(A9,freq_country_man!A:A:freq_country_man!GP:GP,198,0)) -> FALSE | G9: =IF(ISNA(VLOOKUP(A9,freq_country_woman!A:A:freq_country_woman!GQ:GQ,199,0)),0,VLOOKUP(A9,freq_country_woman!A:A:freq_country_woman!GQ:GQ,199,0)) -> 0.58673469 | H9: =IF(ISNA(VLOOKUP(A9,freq_country_man!A:A:freq_country_man!GQ:GQ,199,0)),0,VLOOKUP(A9,freq_country_man!A:A:freq_country_man!GQ:GQ,199,0)) -> 0 | J9: =VLOOKUP(A9,'词频排序表（数据中间处理）'!A:C,3,0) -> 0.991 | K9: =VLOOKUP(A9,'词频排序表（数据中间处理）'!G:I,3,0) -> 0.261 | L9: =IF(ISNA(J9),0,J9)-IF(ISNA(K9),0,K9) -> 0.73 | M9: =VLOOKUP(A9,[1]total_freq!$A:$F,6,0) -> #N/A | N9: =VLOOKUP(A9,[2]total_freq!$A:$F,6,0) -> #N/A | O9: =VLOOKUP(A9,[3]total_freq!$A:$F,6,0) -> #N/A | P9: =VLOOKUP(A9,[4]total_freq!$A:$F,6,0) -> #N/A | Q9: =VLOOKUP(A9,[5]total_freq!$A:$F,6,0) -> #N/A | R9: =VLOOKUP(A9,[6]total_freq!$A:$F,6,0) -> 0.961 | S9: =VLOOKUP(A9,[7]total_freq!$A:$F,6,0) -> 0.977 | T9: =VLOOKUP(A9,[8]total_freq!$A:$F,6,0) -> 0.975 | U9: =VLOOKUP(A9,[9]total_freq!$A:$F,6,0) -> 0.973 | V9: =VLOOKUP(A9,[10]total_freq!$A:$F,6,0) -> 0.62
A10: 负责 | B10: 20 | D10: =OR(E10,F10,G10>0.98,H10>0.98,I10) -> FALSE | E10: =IF(ISNA(VLOOKUP(A10,freq_country_woman!A:A:freq_country_woman!GP:GP,198,0)),FALSE,VLOOKUP(A10,freq_country_woman!A:A:freq_country_woman!GP:GP,198,0)) -> FALSE | F10: =IF(ISNA(VLOOKUP(A10,freq_country_man!A:A:freq_country_man!GP:GP,198,0)),FALSE,VLOOKUP(A10,freq_country_man!A:A:freq_country_man!GP:GP,198,0)) -> FALSE | G10: =IF(ISNA(VLOOKUP(A10,freq_country_woman!A:A:freq_country_woman!GQ:GQ,199,0)),0,VLOOKUP(A10,freq_country_woman!A:A:freq_country_woman!GQ:GQ,199,0)) -> 0.025510204 | H10: =IF(ISNA(VLOOKUP(A10,freq_country_man!A:A:freq_country_man!GQ:GQ,199,0)),0,VLOOKUP(A10,freq_country_man!A:A:freq_country_man!GQ:GQ,199,0)) -> 0 | J10: =VLOOKUP(A10,'词频排序表（数据中间处理）'!A:C,3,0) -> 0.721 | K10: =VLOOKUP(A10,'词频排序表（数据中间处理）'!G:I,3,0) -> #N/A | L10: =IF(ISNA(J10),0,J10)-IF(ISNA(K10),0,K10) -> 0.721 | M10: =VLOOKUP(A10,[1]total_freq!$A:$F,6,0) -> 0.798 | N10: =VLOOKUP(A10,[2]total_freq!$A:$F,6,0) -> 0.683 | O10: =VLOOKUP(A10,[3]total_freq!$A:$F,6,0) -> 0.379 | P10: =VLOOKUP(A10,[4]total_freq!$A:$F,6,0) -> #N/A | Q10: =VLOOKUP(A10,[5]total_freq!$A:$F,6,0) -> 0.002 | R10: =VLOOKUP(A10,[6]total_freq!$A:$F,6,0) -> 0.844 | S10: =VLOOKUP(A10,[7]total_freq!$A:$F,6,0) -> 0.736 | T10: =VLOOKUP(A10,[8]total_freq!$A:$F,6,0) -> #N/A | U10: =VLOOKUP(A10,[9]total_freq!$A:$F,6,0) -> #N/A | V10: =VLOOKUP(A10,[10]total_freq!$A:$F,6,0) -> 0.002
A11: 家务 | B11: 18 | D11: =OR(E11,F11,G11>0.98,H11>0.98,I11) -> FALSE | E11: =IF(ISNA(VLOOKUP(A11,freq_country_woman!A:A:freq_country_woman!GP:GP,198,0)),FALSE,VLOOKUP(A11,freq_country_woman!A:A:freq_country_woman!GP:GP,198,0)) -> FALSE | F11: =IF(ISNA(VLOOKUP(A11,freq_country_man!A:A:freq_country_man!GP:GP,198,0)),FALSE,VLOOKUP(A11,freq_country_man!A:A:freq_country_man!GP:GP,198,0)) -> FALSE | G11: =IF(ISNA(VLOOKUP(A11,freq_country_woman!A:A:freq_country_woman!GQ:GQ,199,0)),0,VLOOKUP(A11,freq_country_woman!A:A:freq_country_woman!GQ:GQ,199,0)) -> 0.015306122 | H11: =IF(ISNA(VLOOKUP(A11,freq_country_man!A:A:freq_country_man!GQ:GQ,199,0)),0,VLOOKUP(A11,freq_country_man!A:A:freq_country_man!GQ:GQ,199,0)) -> 0 | J11: =VLOOKUP(A11,'词频排序表（数据中间处理）'!A:C,3,0) -> 0.701 | K11: =VLOOKUP(A11,'词频排序表（数据中间处理）'!G:I,3,0) -> #N/A | L11: =IF(ISNA(J11),0,J11)-IF(ISNA(K11),0,K11) -> 0.701 | M11: =VLOOKUP(A11,[1]total_freq!$A:$F,6,0) -> 0.431 | N11: =VLOOKUP(A11,[2]total_freq!$A:$F,6,0) -> 0.771 | O11: =VLOOKUP(A11,[3]total_freq!$A:$F,6,0) -> 0.608 | P11: =VLOOKUP(A11,[4]total_freq!$A:$F,6,0) -> 0.411 | Q11: =VLOOKUP(A11,[5]total_freq!$A:$F,6,0) -> 0.409 | R11: =VLOOKUP(A11,[6]total_freq!$A:$F,6,0) -> 0.867 | S11: =VLOOKUP(A11,[7]total_freq!$A:$F,6,0) -> 0.588 | T11: =VLOOKUP(A11,[8]total_freq!$A:$F,6,0) -> #N/A | U11: =VLOOKUP(A11,[9]total_freq!$A:$F,6,0) -> #N/A | V11: =VLOOKUP(A11,[10]total_freq!$A:$F,6,0) -> #N/A
A12: 独立性 | B12: 17 | D12: =OR(E12,F12,G12>0.98,H12>0.98,I12) -> FALSE | E12: =IF(ISNA(VLOOKUP(A12,freq_country_woman!A:A:freq_country_woman!GP:GP,198,0)),FALSE,VLOOKUP(A12,freq_country_woman!A:A:freq_country_woman!GP:GP,198,0)) -> FALSE | F12: =IF(ISNA(VLOOKUP(A12,freq_country_man!A:A:freq_country_man!GP:GP,198,0)),FALSE,VLOOKUP(A12,freq_country_man!A:A:freq_country_man!GP:GP,198,0)) -> FALSE | G12: =IF(ISNA(VLOOKUP(A12,freq_country_woman!A:A:freq_country_woman!GQ:GQ,199,0)),0,VLOOKUP(A12,freq_country_woman!A:A:freq_country_woman!GQ:GQ,199,0)) -> 0.010204082 | H12: =IF(ISNA(VLOOKUP(A12,freq_country_man!A:A:freq_country_man!GQ:GQ,199,0)),0,VLOOKUP(A12,freq_country_man!A:A:freq_country_man!GQ:GQ,199,0)) -> 0 | J12: =VLOOKUP(A12,'词频排序表（数据中间处理）'!A:C,3,0) -> 0.684 | K12: =VLOOKUP(A12,'词频排序表（数据中间处理）'!G:I,3,0) -> #N/A | L12: =IF(ISNA(J12),0,J12)-IF(ISNA(K12),0,K12) -> 0.684 | M12: =VLOOKUP(A12,[1]total_freq!$A:$F,6,0) -> #N/A | N12: =VLOOKUP(A12,[2]total_freq!$A:$F,6,0) -> 0.002 | O12: =VLOOKUP(A12,[3]total_freq!$A:$F,6,0) -> #N/A | P12: =VLOOKUP(A12,[4]total_freq!$A:$F,6,0) -> 0.692 | Q12: =VLOOKUP(A12,[5]total_freq!$A:$F,6,0) -> 0.755 | R12: =VLOOKUP(A12,[6]total_freq!$A:$F,6,0) -> #N/A | S12: =VLOOKUP(A12,[7]total_freq!$A:$F,6,0) -> 0.002 | T12: =VLOOKUP(A12,[8]total_freq!$A:$F,6,0) -> 0.393 | U12: =VLOOKUP(A12,[9]total_freq!$A:$F,6,0) -> 0.763 | V12: =VLOOKUP(A12,[10]total_freq!$A:$F,6,0) -> 0.631
A13: 独立自主 | B13: 16 | D13: =OR(E13,F13,G13>0.98,H13>0.98,I13) -> FALSE | E13: =IF(ISNA(VLOOKUP(A13,freq_country_woman!A:A:freq_country_woman!GP:GP,198,0)),FALSE,VLOOKUP(A13,freq_country_woman!A:A:freq_country_woman!GP:GP,198,0)) -> FALSE | F13: =IF(ISNA(VLOOKUP(A13,freq_country_man!A:A:freq_country_man!GP:GP,198,0)),FALSE,VLOOKUP(A13,freq_country_man!A:A:freq_country_man!GP:GP,198,0)) -> FALSE | G13: =IF(ISNA(VLOOKUP(A13,freq_country_woman!A:A:freq_country_woman!GQ:GQ,199,0)),0,VLOOKUP(A13,freq_country_woman!A:A:freq_country_woman!GQ:GQ,199,0)) -> 0.020408163 | H13: =IF(ISNA(VLOOKUP(A13,freq_country_man!A:A:freq_country_man!GQ:GQ,199,0)),0,VLOOKUP(A13,freq_country_man!A:A:freq_country_man!GQ:GQ,199,0)) -> 0 | J13: =VLOOKUP(A13,'词频排序表（数据中间处理）'!A:C,3,0) -> 0.675 | K13: =VLOOKUP(A13,'词频排序表（数据中间处理）'!G:I,3,0) -> #N/A | L13: =IF(ISNA(J13),0,J13)-IF(ISNA(K13),0,K13) -> 0.675 | M13: =VLOOKUP(A13,[1]total_freq!$A:$F,6,0) -> #N/A | N13: =VLOOKUP(A13,[2]total_freq!$A:$F,6,0) -> #N/A | O13: =VLOOKUP(A13,[3]total_freq!$A:$F,6,0) -> 0.658 | P13: =VLOOKUP(A13,[4]total_freq!$A:$F,6,0) -> 0.644 | Q13: =VLOOKUP(A13,[5]total_freq!$A:$F,6,0) -> 0.605 | R13: =VLOOKUP(A13,[6]total_freq!$A:$F,6,0) -> #N/A | S13: =VLOOKUP(A13,[7]total_freq!$A:$F,6,0) -> #N/A | T13: =VLOOKUP(A13,[8]total_freq!$A:$F,6,0) -> #N/A | U13: =VLOOKUP(A13,[9]total_freq!$A:$F,6,0) -> #N/A | V13: =VLOOKUP(A13,[10]total_freq!$A:$F,6,0) -> 0.894
A14: 深色 | B14: 16 | C14: 2 | D14: =OR(E14,F14,G14>0.98,H14>0.98,I14) -> FALSE | E14: =IF(ISNA(VLOOKUP(A14,freq_country_woman!A:A:freq_country_woman!GP:GP,198,0)),FALSE,VLOOKUP(A14,freq_country_woman!A:A:freq_country_woman!GP:GP,198,0)) -> FALSE | F14: =IF(ISNA(VLOOKUP(A14,freq_country_man!A:A:freq_country_man!GP:GP,198,0)),FALSE,VLOOKUP(A14,freq_country_man!A:A:freq_country_man!GP:GP,198,0)) -> FALSE | G14: =IF(ISNA(VLOOKUP(A14,freq_country_woman!A:A:freq_country_woman!GQ:GQ,199,0)),0,VLOOKUP(A14,freq_country_woman!A:A:freq_country_woman!GQ:GQ,199,0)) -> 0.010204082 | H14: =IF(ISNA(VLOOKUP(A14,freq_country_man!A:A:freq_country_man!GQ:GQ,199,0)),0,VLOOKUP(A14,freq_country_man!A:A:freq_country_man!GQ:GQ,199,0)) -> 0 | J14: =VLOOKUP(A14,'词频排序表（数据中间处理）'!A:C,3,0) -> 0.675 | K14: =VLOOKUP(A14,'词频排序表（数据中间处理）'!G:I,3,0) -> 0.002 | L14: =IF(ISNA(J14),0,J14)-IF(ISNA(K14),0,K14) -> 0.673 | M14: =VLOOKUP(A14,[1]total_freq!$A:$F,6,0) -> 0.002 | N14: =VLOOKUP(A14,[2]total_freq!$A:$F,6,0) -> #N/A | O14: =VLOOKUP(A14,[3]total_freq!$A:$F,6,0) -> 0.656 | P14: =VLOOKUP(A14,[4]total_freq!$A:$F,6,0) -> 0.58 | Q14: =VLOOKUP(A14,[5]total_freq!$A:$F,6,0) -> 0.409 | R14: =VLOOKUP(A14,[6]total_freq!$A:$F,6,0) -> 0.602 | S14: =VLOOKUP(A14,[7]total_freq!$A:$F,6,0) -> 0 | T14: =VLOOKUP(A14,[8]total_freq!$A:$F,6,0) -> 0.612 | U14: =VLOOKUP(A14,[9]total_freq!$A:$F,6,0) -> 0.693 | V14: =VLOOKUP(A14,[10]total_freq!$A:$F,6,0) -> #N/A
A15: 面纱 | B15: 14 | D15: =OR(E15,F15,G15>0.98,H15>0.98,I15) -> FALSE | E15: =IF(ISNA(VLOOKUP(A15,freq_country_woman!A:A:freq_country_woman!GP:GP,198,0)),FALSE,VLOOKUP(A15,freq_country_woman!A:A:freq_country_woman!GP:GP,198,0)) -> FALSE | F15: =IF(ISNA(VLOOKUP(A15,freq_country_man!A:A:freq_country_man!GP:GP,198,0)),FALSE,VLOOKUP(A15,freq_country_man!A:A:freq_country_man!GP:GP,198,0)) -> FALSE | G15: =IF(ISNA(VLOOKUP(A15,freq_country_woman!A:A:freq_country_woman!GQ:GQ,199,0)),0,VLOOKUP(A15,freq_country_woman!A:A:freq_country_woman!GQ:GQ,199,0)) -> 0.020408163 | H15: =IF(ISNA(VLOOKUP(A15,freq_country_man!A:A:freq_country_man!GQ:GQ,199,0)),0,VLOOKUP(A15,freq_country_man!A:A:freq_country_man!GQ:GQ,199,0)) -> 0 | J15: =VLOOKUP(A15,'词频排序表（数据中间处理）'!A:C,3,0) -> 0.637 | K15: =VLOOKUP(A15,'词频排序表（数据中间处理）'!G:I,3,0) -> #N/A | L15: =IF(ISNA(J15),0,J15)-IF(ISNA(K15),0,K15) -> 0.637 | M15: =VLOOKUP(A15,[1]total_freq!$A:$F,6,0) -> 0.854 | N15: =VLOOKUP(A15,[2]total_freq!$A:$F,6,0) -> 0.564 | O15: =VLOOKUP(A15,[3]total_freq!$A:$F,6,0) -> #N/A | P15: =VLOOKUP(A15,[4]total_freq!$A:$F,6,0) -> #N/A | Q15: =VLOOKUP(A15,[5]total_freq!$A:$F,6,0) -> #N/A | R15: =VLOOKUP(A15,[6]total_freq!$A:$F,6,0) -> 0.68 | S15: =VLOOKUP(A15,[7]total_freq!$A:$F,6,0) -> #N/A | T15: =VLOOKUP(A15,[8]total_freq!$A:$F,6,0) -> #N/A | U15: =VLOOKUP(A15,[9]total_freq!$A:$F,6,0) -> 0.625 | V15: =VLOOKUP(A15,[10]total_freq!$A:$F,6,0) -> 0.513
A16: 程度 | B16: 14 | D16: =OR(E16,F16,G16>0.98,H16>0.98,I16) -> FALSE | E16: =IF(ISNA(VLOOKUP(A16,freq_country_woman!A:A:freq_country_woman!GP:GP,198,0)),FALSE,VLOOKUP(A16,freq_country_woman!A:A:freq_country_woman!GP:GP,198,0)) -> FALSE | F16: =IF(ISNA(VLOOKUP(A16,freq_country_man!A:A:freq_country_man!GP:GP,198,0)),FALSE,VLOOKUP(A16,freq_country_man!A:A:freq_country_man!GP:GP,198,0)) -> FALSE | G16: =IF(ISNA(VLOOKUP(A16,freq_country_woman!A:A:freq_country_woman!GQ:GQ,199,0)),0,VLOOKUP(A16,freq_country_woman!A:A:freq_country_woman!GQ:GQ,199,0)) -> 0.015306122 | H16: =IF(ISNA(VLOOKUP(A16,freq_country_man!A:A:freq_country_man!GQ:GQ,199,0)),0,VLOOKUP(A16,freq_country_man!A:A:freq_country_man!GQ:GQ,199,0)) -> 0 | J16: =VLOOKUP(A16,'词频排序表（数据中间处理）'!A:C,3,0) -> 0.637 | K16: =VLOOKUP(A16,'词频排序表（数据中间处理）'!G:I,3,0) -> #N/A | L16: =IF(ISNA(J16),0,J16)-IF(ISNA(K16),0,K16) -> 0.637 | M16: =VLOOKUP(A16,[1]total_freq!$A:$F,6,0) -> 0.431 | N16: =VLOOKUP(A16,[2]total_freq!$A:$F,6,0) -> #N/A | O16: =VLOOKUP(A16,[3]total_freq!$A:$F,6,0) -> 0.379 | P16: =VLOOKUP(A16,[4]total_freq!$A:$F,6,0) -> 0.411 | Q16: =VLOOKUP(A16,[5]total_freq!$A:$F,6,0) -> 0.755 | R16: =VLOOKUP(A16,[6]total_freq!$A:$F,6,0) -> #N/A | S16: =VLOOKUP(A16,[7]total_freq!$A:$F,6,0) -> 0.002 | T16: =VLOOKUP(A16,[8]total_freq!$A:$F,6,0) -> #N/A | U16: =VLOOKUP(A16,[9]total_freq!$A:$F,6,0) -> #N/A | V16: =VLOOKUP(A16,[10]total_freq!$A:$F,6,0) -> 0.882
A17: 职场 | B17: 14 | D17: =OR(E17,F17,G17>0.98,H17>0.98,I17) -> FALSE | E17: =IF(ISNA(VLOOKUP(A17,freq_country_woman!A:A:freq_country_woman!GP:GP,198,0)),FALSE,VLOOKUP(A17,freq_country_woman!A:A:freq_country_woman!GP:GP,198,0)) -> FALSE | F17: =IF(ISNA(VLOOKUP(A17,freq_country_man!A:A:freq_country_man!GP:GP,198,0)),FALSE,VLOOKUP(A17,freq_country_man!A:A:freq_country_man!GP:GP,198,0)) -> FALSE | G17: =IF(ISNA(VLOOKUP(A17,freq_country_woman!A:A:freq_country_woman!GQ:GQ,199,0)),0,VLOOKUP(A17,freq_country_woman!A:A:freq_country_woman!GQ:GQ,199,0)) -> 0.0051020408 | H17: =IF(ISNA(VLOOKUP(A17,freq_country_man!A:A:freq_country_man!GQ:GQ,199,0)),0,VLOOKUP(A17,freq_country_man!A:A:freq_country_man!GQ:GQ,199,0)) -> 0 | J17: =VLOOKUP(A17,'词频排序表（数据中间处理）'!A:C,3,0) -> 0.637 | K17: =VLOOKUP(A17,'词频排序表（数据中间处理）'!G:I,3,0) -> #N/A | L17: =IF(ISNA(J17),0,J17)-IF(ISNA(K17),0,K17) -> 0.637 | M17: =VLOOKUP(A17,[1]total_freq!$A:$F,6,0) -> 0.002 | N17: =VLOOKUP(A17,[2]total_freq!$A:$F,6,0) -> 0.002 | O17: =VLOOKUP(A17,[3]total_freq!$A:$F,6,0) -> 0.379 | P17: =VLOOKUP(A17,[4]total_freq!$A:$F,6,0) -> 0.411 | Q17: =VLOOKUP(A17,[5]total_freq!$A:$F,6,0) -> 0.755 | R17: =VLOOKUP(A17,[6]total_freq!$A:$F,6,0) -> #N/A | S17: =VLOOKUP(A17,[7]total_freq!$A:$F,6,0) -> 0.374 | T17: =VLOOKUP(A17,[8]total_freq!$A:$F,6,0) -> 0.393 | U17: =VLOOKUP(A17,[9]total_freq!$A:$F,6,0) -> 0.492 | V17: =VLOOKUP(A17,[10]total_freq!$A:$F,6,0) -> 0.705
A18: 劳动 | B18: 14 | D18: =OR(E18,F18,G18>0.98,H18>0.98,I18) -> FALSE | E18: =IF(ISNA(VLOOKUP(A18,freq_country_woman!A:A:freq_country_woman!GP:GP,198,0)),FALSE,VLOOKUP(A18,freq_country_woman!A:A:freq_country_woman!GP:GP,198,0)) -> FALSE | F18: =IF(ISNA(VLOOKUP(A18,freq_country_man!A:A:freq_country_man!GP:GP,198,0)),FALSE,VLOOKUP(A18,freq_country_man!A:A:freq_country_man!GP:GP,198,0)) -> FALSE | G18: =IF(ISNA(VLOOKUP(A18,freq_country_woman!A:A:freq_country_woman!GQ:GQ,199,0)),0,VLOOKUP(A18,freq_country_woman!A:A:freq_country_woman!GQ:GQ,199,0)) -> 0.010204082 | H18: =IF(ISNA(VLOOKUP(A18,freq_country_man!A:A:freq_country_man!GQ:GQ,199,0)),0,VLOOKUP(A18,freq_country_man!A:A:freq_country_man!GQ:GQ,199,0)) -> 0 | J18: =VLOOKUP(A18,'词频排序表（数据中间处理）'!A:C,3,0) -> 0.637 | K18: =VLOOKUP(A18,'词频排序表（数据中间处理）'!G:I,3,0) -> #N/A | L18: =IF(ISNA(J18),0,J18)-IF(ISNA(K18),0,K18) -> 0.637 | M18: =VLOOKUP(A18,[1]total_freq!$A:$F,6,0) -> 0.002 | N18: =VLOOKUP(A18,[2]total_freq!$A:$F,6,0) -> 0.564 | O18: =VLOOKUP(A18,[3]total_freq!$A:$F,6,0) -> 0.768 | P18: =VLOOKUP(A18,[4]total_freq!$A:$F,6,0) -> 0.002 | Q18: =VLOOKUP(A18,[5]total_freq!$A:$F,6,0) -> #N/A | R18: =VLOOKUP(A18,[6]total_freq!$A:$F,6,0) -> 0.849 | S18: =VLOOKUP(A18,[7]total_freq!$A:$F,6,0) -> 0.374 | T18: =VLOOKUP(A18,[8]total_freq!$A:$F,6,0) -> #N/A | U18: =VLOOKUP(A18,[9]total_freq!$A:$F,6,0) -> #N/A | V18: =VLOOKUP(A18,[10]total_freq!$A:$F,6,0) -> #N/A
A19: 外貌 | B19: 14 | C19: 2 | D19: =OR(E19,F19,G19>0.98,H19>0.98,I19) -> FALSE | E19: =IF(ISNA(VLOOKUP(A19,freq_country_woman!A:A:freq_country_woman!GP:GP,198,0)),FALSE,VLOOKUP(A19,freq_country_woman!A:A:freq_country_woman!GP:GP,198,0)) -> FALSE | F19: =IF(ISNA(VLOOKUP(A19,freq_country_man!A:A:freq_country_man!GP:GP,198,0)),FALSE,VLOOKUP(A19,freq_country_man!A:A:freq_country_man!GP:GP,198,0)) -> FALSE | G19: =IF(ISNA(VLOOKUP(A19,freq_country_woman!A:A:freq_country_woman!GQ:GQ,199,0)),0,VLOOKUP(A19,freq_country_woman!A:A:freq_country_woman!GQ:GQ,199,0)) -> 0.010204082 | H19: =IF(ISNA(VLOOKUP(A19,freq_country_man!A:A:freq_country_man!GQ:GQ,199,0)),0,VLOOKUP(A19,freq_country_man!A:A:freq_country_man!GQ:GQ,199,0)) -> 0 | J19: =VLOOKUP(A19,'词频排序表（数据中间处理）'!A:C,3,0) -> 0.637 | K19: =VLOOKUP(A19,'词频排序表（数据中间处理）'!G:I,3,0) -> 0.002 | L19: =IF(ISNA(J19),0,J19)-IF(ISNA(K19),0,K19) -> 0.635 | M19: =VLOOKUP(A19,[1]total_freq!$A:$F,6,0) -> #N/A | N19: =VLOOKUP(A19,[2]total_freq!$A:$F,6,0) -> 0.002 | O19: =VLOOKUP(A19,[3]total_freq!$A:$F,6,0) -> 0.606 | P19: =VLOOKUP(A19,[4]total_freq!$A:$F,6,0) -> 0.642 | Q19: =VLOOKUP(A19,[5]total_freq!$A:$F,6,0) -> 0.605 | R19: =VLOOKUP(A19,[6]total_freq!$A:$F,6,0) -> #N/A | S19: =VLOOKUP(A19,[7]total_freq!$A:$F,6,0) -> 0.194 | T19: =VLOOKUP(A19,[8]total_freq!$A:$F,6,0) -> #N/A | U19: =VLOOKUP(A19,[9]total_freq!$A:$F,6,0) -> 0.811 | V19: =VLOOKUP(A19,[10]total_freq!$A:$F,6,0) -> #N/A
A20: 为重 | B20: 14 | C20: 2 | D20: =OR(E20,F20,G20>0.98,H20>0.98,I20) -> FALSE | E20: =IF(ISNA(VLOOKUP(A20,freq_country_woman!A:A:freq_country_woman!GP:GP,198,0)),FALSE,VLOOKUP(A20,freq_country_woman!A:A:freq_country_woman!GP:GP,198,0)) -> FALSE | F20: =IF(ISNA(VLOOKUP(A20,freq_country_man!A:A:freq_country_man!GP:GP,198,0)),FALSE,VLOOKUP(A20,freq_country_man!A:A:freq_country_man!GP:GP,198,0)) -> FALSE | G20: =IF(ISNA(VLOOKUP(A20,freq_country_woman!A:A:freq_country_woman!GQ:GQ,199,0)),0,VLOOKUP(A20,freq_country_woman!A:A:freq_country_woman!GQ:GQ,199,0)) -> 0.0051020408 | H20: =IF(ISNA(VLOOKUP(A20,freq_country_man!A:A:freq_country_man!GQ:GQ,199,0)),0,VLOOKUP(A20,freq_country_man!A:A:freq_country_man!GQ:GQ,199,0)) -> 0 | J20: =VLOOKUP(A20,'词频排序表（数据中间处理）'!A:C,3,0) -> 0.637 | K20: =VLOOKUP(A20,'词频排序表（数据中间处理）'!G:I,3,0) -> 0.002 | L20: =IF(ISNA(J20),0,J20)-IF(ISNA(K20),0,K20) -> 0.635 | M20: =VLOOKUP(A20,[1]total_freq!$A:$F,6,0) -> 0.682 | N20: =VLOOKUP(A20,[2]total_freq!$A:$F,6,0) -> 0.683 | O20: =VLOOKUP(A20,[3]total_freq!$A:$F,6,0) -> 0.379 | P20: =VLOOKUP(A20,[4]total_freq!$A:$F,6,0) -> 0.002 | Q20: =VLOOKUP(A20,[5]total_freq!$A:$F,6,0) -> -0.002 | R20: =VLOOKUP(A20,[6]total_freq!$A:$F,6,0) -> 0.722 | S20: =VLOOKUP(A20,[7]total_freq!$A:$F,6,0) -> 0.522 | T20: =VLOOKUP(A20,[8]total_freq!$A:$F,6,0) -> 0.536 | U20: =VLOOKUP(A20,[9]total_freq!$A:$F,6,0) -> 0 | V20: =VLOOKUP(A20,[10]total_freq!$A:$F,6,0) -> #N/A
A21: 公共场合 | B21: 27 | C21: 3 | D21: =OR(E21,F21,G21>0.98,H21>0.98,I21) -> FALSE | E21: =IF(ISNA(VLOOKUP(A21,freq_country_woman!A:A:freq_country_woman!GP:GP,198,0)),FALSE,VLOOKUP(A21,freq_country_woman!A:A:freq_country_woman!GP:GP,198,0)) -> FALSE | F21: =IF(ISNA(VLOOKUP(A21,freq_country_man!A:A:freq_country_man!GP:GP,198,0)),FALSE,VLOOKUP(A21,freq_country_man!A:A:freq_country_man!GP:GP,198,0)) -> FALSE | G21: =IF(ISNA(VLOOKUP(A21,freq_country_woman!A:A:freq_country_woman!GQ:GQ,199,0)),0,VLOOKUP(A21,freq_country_woman!A:A:freq_country_woman!GQ:GQ,199,0)) -> 0.045918367 | H21: =IF(ISNA(VLOOKUP(A21,freq_country_man!A:A:freq_country_man!GQ:GQ,199,0)),0,VLOOKUP(A21,freq_country_man!A:A:freq_country_man!GQ:GQ,199,0)) -> 0 | J21: =VLOOKUP(A21,'词频排序表（数据中间处理）'!A:C,3,0) -> 0.781 | K21: =VLOOKUP(A21,'词频排序表（数据中间处理）'!G:I,3,0) -> 0.15 | L21: =IF(ISNA(J21),0,J21)-IF(ISNA(K21),0,K21) -> 0.631 | M21: =VLOOKUP(A21,[1]total_freq!$A:$F,6,0) -> 0.887 | N21: =VLOOKUP(A21,[2]total_freq!$A:$F,6,0) -> 0.806 | O21: =VLOOKUP(A21,[3]total_freq!$A:$F,6,0) -> 0.377 | P21: =VLOOKUP(A21,[4]total_freq!$A:$F,6,0) -> #N/A | Q21: =VLOOKUP(A21,[5]total_freq!$A:$F,6,0) -> #N/A | R21: =VLOOKUP(A21,[6]total_freq!$A:$F,6,0) -> 0.529 | S21: =VLOOKUP(A21,[7]total_freq!$A:$F,6,0) -> 0.662 | T21: =VLOOKUP(A21,[8]total_freq!$A:$F,6,0) -> 0.538 | U21: =VLOOKUP(A21,[9]total_freq!$A:$F,6,0) -> 0.693 | V21: =VLOOKUP(A21,[10]total_freq!$A:$F,6,0) -> 0.348
A22: 性别 | B22: 24 | C22: 3 | D22: =OR(E22,F22,G22>0.98,H22>0.98,I22) -> FALSE | E22: =IF(ISNA(VLOOKUP(A22,freq_country_woman!A:A:freq_country_woman!GP:GP,198,0)),FALSE,VLOOKUP(A22,freq_country_woman!A:A:freq_country_woman!GP:GP,198,0)) -> FALSE | F22: =IF(ISNA(VLOOKUP(A22,freq_country_man!A:A:freq_country_man!GP:GP,198,0)),FALSE,VLOOKUP(A22,freq_country_man!A:A:freq_country_man!GP:GP,198,0)) -> FALSE | G22: =IF(ISNA(VLOOKUP(A22,freq_country_woman!A:A:freq_country_woman!GQ:GQ,199,0)),0,VLOOKUP(A22,freq_country_woman!A:A:freq_country_woman!GQ:GQ,199,0)) -> 0.020408163 | H22: =IF(ISNA(VLOOKUP(A22,freq_country_man!A:A:freq_country_man!GQ:GQ,199,0)),0,VLOOKUP(A22,freq_country_man!A:A:freq_country_man!GQ:GQ,199,0)) -> 0 | J22: =VLOOKUP(A22,'词频排序表（数据中间处理）'!A:C,3,0) -> 0.768 | K22: =VLOOKUP(A22,'词频排序表（数据中间处理）'!G:I,3,0) -> 0.15 | L22: =IF(ISNA(J22),0,J22)-IF(ISNA(K22),0,K22) -> 0.618 | M22: =VLOOKUP(A22,[1]total_freq!$A:$F,6,0) -> 0.431 | N22: =VLOOKUP(A22,[2]total_freq!$A:$F,6,0) -> 0.745 | O22: =VLOOKUP(A22,[3]total_freq!$A:$F,6,0) -> 0.379 | P22: =VLOOKUP(A22,[4]total_freq!$A:$F,6,0) -> 0.411 | Q22: =VLOOKUP(A22,[5]total_freq!$A:$F,6,0) -> 0.241 | R22: =VLOOKUP(A22,[6]total_freq!$A:$F,6,0) -> #N/A | S22: =VLOOKUP(A22,[7]total_freq!$A:$F,6,0) -> 0.588 | T22: =VLOOKUP(A22,[8]total_freq!$A:$F,6,0) -> #N/A | U22: =VLOOKUP(A22,[9]total_freq!$A:$F,6,0) -> 0.695 | V22: =VLOOKUP(A22,[10]total_freq!$A:$F,6,0) -> 0.352
A23: 韧性 | B23: 12 | C23: 2 | D23: =OR(E23,F23,G23>0.98,H23>0.98,I23) -> FALSE | E23: =IF(ISNA(VLOOKUP(A23,freq_country_woman!A:A:freq_country_woman!GP:GP,198,0)),FALSE,VLOOKUP(A23,freq_country_woman!A:A:freq_country_woman!GP:GP,198,0)) -> FALSE | F23: =IF(ISNA(VLOOKUP(A23,freq_country_man!A:A:freq_country_man!GP:GP,198,0)),FALSE,VLOOKUP(A23,freq_country_man!A:A:freq_country_man!GP:GP,198,0)) -> FALSE | G23: =IF(ISNA(VLOOKUP(A23,freq_country_woman!A:A:freq_country_woman!GQ:GQ,199,0)),0,VLOOKUP(A23,freq_country_woman!A:A:freq_country_woman!GQ:GQ,199,0)) -> 0.0051020408 | H23: =IF(ISNA(VLOOKUP(A23,freq_country_man!A:A:freq_country_man!GQ:GQ,199,0)),0,VLOOKUP(A23,freq_country_man!A:A:freq_country_man!GQ:GQ,199,0)) -> 0 | J23: =VLOOKUP(A23,'词频排序表（数据中间处理）'!A:C,3,0) -> 0.602 | K23: =VLOOKUP(A23,'词频排序表（数据中间处理）'!G:I,3,0) -> 0.002 | L23: =IF(ISNA(J23),0,J23)-IF(ISNA(K23),0,K23) -> 0.6 | M23: =VLOOKUP(A23,[1]total_freq!$A:$F,6,0) -> 0.554 | N23: =VLOOKUP(A23,[2]total_freq!$A:$F,6,0) -> 0.683 | O23: =VLOOKUP(A23,[3]total_freq!$A:$F,6,0) -> 0.377 | P23: =VLOOKUP(A23,[4]total_freq!$A:$F,6,0) -> 0.411 | Q23: =VLOOKUP(A23,[5]total_freq!$A:$F,6,0) -> #N/A | R23: =VLOOKUP(A23,[6]total_freq!$A:$F,6,0) -> 0.743 | S23: =VLOOKUP(A23,[7]total_freq!$A:$F,6,0) -> 0.372 | T23: =VLOOKUP(A23,[8]total_freq!$A:$F,6,0) -> 0.393 | U23: =VLOOKUP(A23,[9]total_freq!$A:$F,6,0) -> #N/A | V23: =VLOOKUP(A23,[10]total_freq!$A:$F,6,0) -> #N/A
A24: 黑袍 | B24: 11 | D24: =OR(E24,F24,G24>0.98,H24>0.98,I24) -> FALSE | E24: =IF(ISNA(VLOOKUP(A24,freq_country_woman!A:A:freq_country_woman!GP:GP,198,0)),FALSE,VLOOKUP(A24,freq_country_woman!A:A:freq_country_woman!GP:GP,198,0)) -> FALSE | F24: =IF(ISNA(VLOOKUP(A24,freq_country_man!A:A:freq_country_man!GP:GP,198,0)),FALSE,VLOOKUP(A24,freq_country_man!A:A:freq_country_man!GP:GP,198,0)) -> FALSE | G24: =IF(ISNA(VLOOKUP(A24,freq_country_woman!A:A:freq_country_woman!GQ:GQ,199,0)),0,VLOOKUP(A24,freq_country_woman!A:A:freq_country_woman!GQ:GQ,199,0)) -> 0.010204082 | H24: =IF(ISNA(VLOOKUP(A24,freq_country_man!A:A:freq_country_man!GQ:GQ,199,0)),0,VLOOKUP(A24,freq_country_man!A:A:freq_country_man!GQ:GQ,199,0)) -> 0 | J24: =VLOOKUP(A24,'词频排序表（数据中间处理）'!A:C,3,0) -> 0.573 | K24: =VLOOKUP(A24,'词频排序表（数据中间处理）'!G:I,3,0) -> #N/A | L24: =IF(ISNA(J24),0,J24)-IF(ISNA(K24),0,K24) -> 0.573 | M24: =VLOOKUP(A24,[1]total_freq!$A:$F,6,0) -> 0.684 | N24: =VLOOKUP(A24,[2]total_freq!$A:$F,6,0) -> 0.426 | O24: =VLOOKUP(A24,[3]total_freq!$A:$F,6,0) -> 0.533 | P24: =VLOOKUP(A24,[4]total_freq!$A:$F,6,0) -> #N/A | Q24: =VLOOKUP(A24,[5]total_freq!$A:$F,6,0) -> #N/A | R24: =VLOOKUP(A24,[6]total_freq!$A:$F,6,0) -> 0.002 | S24: =VLOOKUP(A24,[7]total_freq!$A:$F,6,0) -> #N/A | T24: =VLOOKUP(A24,[8]total_freq!$A:$F,6,0) -> 0.002 | U24: =VLOOKUP(A24,[9]total_freq!$A:$F,6,0) -> 0.374 | V24: =VLOOKUP(A24,[10]total_freq!$A:$F,6,0) -> 0.705
A25: 风情 | B25: 11 | C25: 2 | D25: =OR(E25,F25,G25>0.98,H25>0.98,I25) -> FALSE | E25: =IF(ISNA(VLOOKUP(A25,freq_country_woman!A:A:freq_country_woman!GP:GP,198,0)),FALSE,VLOOKUP(A25,freq_country_woman!A:A:freq_country_woman!GP:GP,198,0)) -> FALSE | F25: =IF(ISNA(VLOOKUP(A25,freq_country_man!A:A:freq_country_man!GP:GP,198,0)),FALSE,VLOOKUP(A25,freq_country_man!A:A:freq_country_man!GP:GP,198,0)) -> FALSE | G25: =IF(ISNA(VLOOKUP(A25,freq_country_woman!A:A:freq_country_woman!GQ:GQ,199,0)),0,VLOOKUP(A25,freq_country_woman!A:A:freq_country_woman!GQ:GQ,199,0)) -> 0.015306122 | H25: =IF(ISNA(VLOOKUP(A25,freq_country_man!A:A:freq_country_man!GQ:GQ,199,0)),0,VLOOKUP(A25,freq_country_man!A:A:freq_country_man!GQ:GQ,199,0)) -> 0 | J25: =VLOOKUP(A25,'词频排序表（数据中间处理）'!A:C,3,0) -> 0.573 | K25: =VLOOKUP(A25,'词频排序表（数据中间处理）'!G:I,3,0) -> 0.002 | L25: =IF(ISNA(J25),0,J25)-IF(ISNA(K25),0,K25) -> 0.571 | M25: =VLOOKUP(A25,[1]total_freq!$A:$F,6,0) -> #N/A | N25: =VLOOKUP(A25,[2]total_freq!$A:$F,6,0) -> 0.002 | O25: =VLOOKUP(A25,[3]total_freq!$A:$F,6,0) -> 0.379 | P25: =VLOOKUP(A25,[4]total_freq!$A:$F,6,0) -> 0 | Q25: =VLOOKUP(A25,[5]total_freq!$A:$F,6,0) -> 0.646 | R25: =VLOOKUP(A25,[6]total_freq!$A:$F,6,0) -> #N/A | S25: =VLOOKUP(A25,[7]total_freq!$A:$F,6,0) -> -0.002 | T25: =VLOOKUP(A25,[8]total_freq!$A:$F,6,0) -> #N/A | U25: =VLOOKUP(A25,[9]total_freq!$A:$F,6,0) -> 0.737 | V25: =VLOOKUP(A25,[10]total_freq!$A:$F,6,0) -> 0.513
A26: 独特 | B26: 20 | C26: 3 | D26: =OR(E26,F26,G26>0.98,H26>0.98,I26) -> FALSE | E26: =IF(ISNA(VLOOKUP(A26,freq_country_woman!A:A:freq_country_woman!GP:GP,198,0)),FALSE,VLOOKUP(A26,freq_country_woman!A:A:freq_country_woman!GP:GP,198,0)) -> FALSE | F26: =IF(ISNA(VLOOKUP(A26,freq_country_man!A:A:freq_country_man!GP:GP,198,0)),FALSE,VLOOKUP(A26,freq_country_man!A:A:freq_country_man!GP:GP,198,0)) -> FALSE | G26: =IF(ISNA(VLOOKUP(A26,freq_country_woman!A:A:freq_country_woman!GQ:GQ,199,0)),0,VLOOKUP(A26,freq_country_woman!A:A:freq_country_woman!GQ:GQ,199,0)) -> 0.015306122 | H26: =IF(ISNA(VLOOKUP(A26,freq_country_man!A:A:freq_country_man!GQ:GQ,199,0)),0,VLOOKUP(A26,freq_country_man!A:A:freq_country_man!GQ:GQ,199,0)) -> 0 | J26: =VLOOKUP(A26,'词频排序表（数据中间处理）'!A:C,3,0) -> 0.721 | K26: =VLOOKUP(A26,'词频排序表（数据中间处理）'!G:I,3,0) -> 0.15 | L26: =IF(ISNA(J26),0,J26)-IF(ISNA(K26),0,K26) -> 0.571 | M26: =VLOOKUP(A26,[1]total_freq!$A:$F,6,0) -> 0.002 | N26: =VLOOKUP(A26,[2]total_freq!$A:$F,6,0) -> 0.426 | O26: =VLOOKUP(A26,[3]total_freq!$A:$F,6,0) -> 0.766 | P26: =VLOOKUP(A26,[4]total_freq!$A:$F,6,0) -> 0.002 | Q26: =VLOOKUP(A26,[5]total_freq!$A:$F,6,0) -> 0.736 | R26: =VLOOKUP(A26,[6]total_freq!$A:$F,6,0) -> 0.649 | S26: =VLOOKUP(A26,[7]total_freq!$A:$F,6,0) -> 0.522 | T26: =VLOOKUP(A26,[8]total_freq!$A:$F,6,0) -> 0.536 | U26: =VLOOKUP(A26,[9]total_freq!$A:$F,6,0) -> 0.575 | V26: =VLOOKUP(A26,[10]total_freq!$A:$F,6,0) -> 0.63
A27: 并存 | B27: 20 | C27: 3 | D27: =OR(E27,F27,G27>0.98,H27>0.98,I27) -> FALSE | E27: =IF(ISNA(VLOOKUP(A27,freq_country_woman!A:A:freq_country_woman!GP:GP,198,0)),FALSE,VLOOKUP(A27,freq_country_woman!A:A:freq_country_woman!GP:GP,198,0)) -> FALSE | F27: =IF(ISNA(VLOOKUP(A27,freq_country_man!A:A:freq_country_man!GP:GP,198,0)),FALSE,VLOOKUP(A27,freq_country_man!A:A:freq_country_man!GP:GP,198,0)) -> FALSE | G27: =IF(ISNA(VLOOKUP(A27,freq_country_woman!A:A:freq_country_woman!GQ:GQ,199,0)),0,VLOOKUP(A27,freq_country_woman!A:A:freq_country_woman!GQ:GQ,199,0)) -> 0.020408163 | H27: =IF(ISNA(VLOOKUP(A27,freq_country_man!A:A:freq_country_man!GQ:GQ,199,0)),0,VLOOKUP(A27,freq_country_man!A:A:freq_country_man!GQ:GQ,199,0)) -> 0 | J27: =VLOOKUP(A27,'词频排序表（数据中间处理）'!A:C,3,0) -> 0.721 | K27: =VLOOKUP(A27,'词频排序表（数据中间处理）'!G:I,3,0) -> 0.15 | L27: =IF(ISNA(J27),0,J27)-IF(ISNA(K27),0,K27) -> 0.571 | M27: =VLOOKUP(A27,[1]total_freq!$A:$F,6,0) -> 0.554 | N27: =VLOOKUP(A27,[2]total_freq!$A:$F,6,0) -> 0.808 | O27: =VLOOKUP(A27,[3]total_freq!$A:$F,6,0) -> 0.606 | P27: =VLOOKUP(A27,[4]total_freq!$A:$F,6,0) -> #N/A | Q27: =VLOOKUP(A27,[5]total_freq!$A:$F,6,0) -> 0.407 | R27: =VLOOKUP(A27,[6]total_freq!$A:$F,6,0) -> 0.394 | S27: =VLOOKUP(A27,[7]total_freq!$A:$F,6,0) -> 0.778 | T27: =VLOOKUP(A27,[8]total_freq!$A:$F,6,0) -> 0.682 | U27: =VLOOKUP(A27,[9]total_freq!$A:$F,6,0) -> 0.49 | V27: =VLOOKUP(A27,[10]total_freq!$A:$F,6,0) -> -0.373
A28: 皮肤 | B28: 19 | C28: 3 | D28: =OR(E28,F28,G28>0.98,H28>0.98,I28) -> FALSE | E28: =IF(ISNA(VLOOKUP(A28,freq_country_woman!A:A:freq_country_woman!GP:GP,198,0)),FALSE,VLOOKUP(A28,freq_country_woman!A:A:freq_country_woman!GP:GP,198,0)) -> FALSE | F28: =IF(ISNA(VLOOKUP(A28,freq_country_man!A:A:freq_country_man!GP:GP,198,0)),FALSE,VLOOKUP(A28,freq_country_man!A:A:freq_country_man!GP:GP,198,0)) -> FALSE | G28: =IF(ISNA(VLOOKUP(A28,freq_country_woman!A:A:freq_country_woman!GQ:GQ,199,0)),0,VLOOKUP(A28,freq_country_woman!A:A:freq_country_woman!GQ:GQ,199,0)) -> 0.020408163 | H28: =IF(ISNA(VLOOKUP(A28,freq_country_man!A:A:freq_country_man!GQ:GQ,199,0)),0,VLOOKUP(A28,freq_country_man!A:A:freq_country_man!GQ:GQ,199,0)) -> 0 | J28: =VLOOKUP(A28,'词频排序表（数据中间处理）'!A:C,3,0) -> 0.713 | K28: =VLOOKUP(A28,'词频排序表（数据中间处理）'!G:I,3,0) -> 0.15 | L28: =IF(ISNA(J28),0,J28)-IF(ISNA(K28),0,K28) -> 0.563 | M28: =VLOOKUP(A28,[1]total_freq!$A:$F,6,0) -> 0.002 | N28: =VLOOKUP(A28,[2]total_freq!$A:$F,6,0) -> 0.562 | O28: =VLOOKUP(A28,[3]total_freq!$A:$F,6,0) -> 0.606 | P28: =VLOOKUP(A28,[4]total_freq!$A:$F,6,0) -> 0.411 | Q28: =VLOOKUP(A28,[5]total_freq!$A:$F,6,0) -> 0.53 | R28: =VLOOKUP(A28,[6]total_freq!$A:$F,6,0) -> 0.602 | S28: =VLOOKUP(A28,[7]total_freq!$A:$F,6,0) -> 0 | T28: =VLOOKUP(A28,[8]total_freq!$A:$F,6,0) -> 0.536 | U28: =VLOOKUP(A28,[9]total_freq!$A:$F,6,0) -> 0.862 | V28: =VLOOKUP(A28,[10]total_freq!$A:$F,6,0) -> #N/A
A29: 中心 | B29: 36 | C29: 4 | D29: =OR(E29,F29,G29>0.98,H29>0.98,I29) -> FALSE | E29: =IF(ISNA(VLOOKUP(A29,freq_country_woman!A:A:freq_country_woman!GP:GP,198,0)),FALSE,VLOOKUP(A29,freq_country_woman!A:A:freq_country_woman!GP:GP,198,0)) -> FALSE | F29: =IF(ISNA(VLOOKUP(A29,freq_country_man!A:A:freq_country_man!GP:GP,198,0)),FALSE,VLOOKUP(A29,freq_country_man!A:A:freq_country_man!GP:GP,198,0)) -> FALSE | G29: =IF(ISNA(VLOOKUP(A29,freq_country_woman!A:A:freq_country_woman!GQ:GQ,199,0)),0,VLOOKUP(A29,freq_country_woman!A:A:freq_country_woman!GQ:GQ,199,0)) -> 0.025510204 | H29: =IF(ISNA(VLOOKUP(A29,freq_country_man!A:A:freq_country_man!GQ:GQ,199,0)),0,VLOOKUP(A29,freq_country_man!A:A:freq_country_man!GQ:GQ,199,0)) -> 0 | J29: =VLOOKUP(A29,'词频排序表（数据中间处理）'!A:C,3,0) -> 0.823 | K29: =VLOOKUP(A29,'词频排序表（数据中间处理）'!G:I,3,0) -> 0.261 | L29: =IF(ISNA(J29),0,J29)-IF(ISNA(K29),0,K29) -> 0.562 | M29: =VLOOKUP(A29,[1]total_freq!$A:$F,6,0) -> 0.764 | N29: =VLOOKUP(A29,[2]total_freq!$A:$F,6,0) -> 0.769 | O29: =VLOOKUP(A29,[3]total_freq!$A:$F,6,0) -> 0.73 | P29: =VLOOKUP(A29,[4]total_freq!$A:$F,6,0) -> 0.692 | Q29: =VLOOKUP(A29,[5]total_freq!$A:$F,6,0) -> -0.391 | R29: =VLOOKUP(A29,[6]total_freq!$A:$F,6,0) -> 0.798 | S29: =VLOOKUP(A29,[7]total_freq!$A:$F,6,0) -> 0.847 | T29: =VLOOKUP(A29,[8]total_freq!$A:$F,6,0) -> 0.393 | U29: =VLOOKUP(A29,[9]total_freq!$A:$F,6,0) -> 0.374 | V29: =VLOOKUP(A29,[10]total_freq!$A:$F,6,0) -> 0.513
A30: 气质 | B30: 18 | C30: 3 | D30: =OR(E30,F30,G30>0.98,H30>0.98,I30) -> FALSE | E30: =IF(ISNA(VLOOKUP(A30,freq_country_woman!A:A:freq_country_woman!GP:GP,198,0)),FALSE,VLOOKUP(A30,freq_country_woman!A:A:freq_country_woman!GP:GP,198,0)) -> FALSE | F30: =IF(ISNA(VLOOKUP(A30,freq_country_man!A:A:freq_country_man!GP:GP,198,0)),FALSE,VLOOKUP(A30,freq_country_man!A:A:freq_country_man!GP:GP,198,0)) -> FALSE | G30: =IF(ISNA(VLOOKUP(A30,freq_country_woman!A:A:freq_country_woman!GQ:GQ,199,0)),0,VLOOKUP(A30,freq_country_woman!A:A:freq_country_woman!GQ:GQ,199,0)) -> 0.025510204 | H30: =IF(ISNA(VLOOKUP(A30,freq_country_man!A:A:freq_country_man!GQ:GQ,199,0)),0,VLOOKUP(A30,freq_country_man!A:A:freq_country_man!GQ:GQ,199,0)) -> 0 | J30: =VLOOKUP(A30,'词频排序表（数据中间处理）'!A:C,3,0) -> 0.701 | K30: =VLOOKUP(A30,'词频排序表（数据中间处理）'!G:I,3,0) -> 0.15 | L30: =IF(ISNA(J30),0,J30)-IF(ISNA(K30),0,K30) -> 0.551 | M30: =VLOOKUP(A30,[1]total_freq!$A:$F,6,0) -> #N/A | N30: =VLOOKUP(A30,[2]total_freq!$A:$F,6,0) -> #N/A | O30: =VLOOKUP(A30,[3]total_freq!$A:$F,6,0) -> 0.379 | P30: =VLOOKUP(A30,[4]total_freq!$A:$F,6,0) -> #N/A | Q30: =VLOOKUP(A30,[5]total_freq!$A:$F,6,0) -> 0.481 | R30: =VLOOKUP(A30,[6]total_freq!$A:$F,6,0) -> #N/A | S30: =VLOOKUP(A30,[7]total_freq!$A:$F,6,0) -> 0.374 | T30: =VLOOKUP(A30,[8]total_freq!$A:$F,6,0) -> 0.002 | U30: =VLOOKUP(A30,[9]total_freq!$A:$F,6,0) -> 0.693 | V30: =VLOOKUP(A30,[10]total_freq!$A:$F,6,0) -> 0.348
A31: 严格 | B31: 17 | C31: 3 | D31: =OR(E31,F31,G31>0.98,H31>0.98,I31) -> FALSE | E31: =IF(ISNA(VLOOKUP(A31,freq_country_woman!A:A:freq_country_woman!GP:GP,198,0)),FALSE,VLOOKUP(A31,freq_country_woman!A:A:freq_country_woman!GP:GP,198,0)) -> FALSE | F31: =IF(ISNA(VLOOKUP(A31,freq_country_man!A:A:freq_country_man!GP:GP,198,0)),FALSE,VLOOKUP(A31,freq_country_man!A:A:freq_country_man!GP:GP,198,0)) -> FALSE | G31: =IF(ISNA(VLOOKUP(A31,freq_country_woman!A:A:freq_country_woman!GQ:GQ,199,0)),0,VLOOKUP(A31,freq_country_woman!A:A:freq_country_woman!GQ:GQ,199,0)) -> 0.015306122 | H31: =IF(ISNA(VLOOKUP(A31,freq_country_man!A:A:freq_country_man!GQ:GQ,199,0)),0,VLOOKUP(A31,freq_country_man!A:A:freq_country_man!GQ:GQ,199,0)) -> 0.0051020408 | J31: =VLOOKUP(A31,'词频排序表（数据中间处理）'!A:C,3,0) -> 0.684 | K31: =VLOOKUP(A31,'词频排序表（数据中间处理）'!G:I,3,0) -> 0.15 | L31: =IF(ISNA(J31),0,J31)-IF(ISNA(K31),0,K31) -> 0.534 | M31: =VLOOKUP(A31,[1]total_freq!$A:$F,6,0) -> 0.736 | N31: =VLOOKUP(A31,[2]total_freq!$A:$F,6,0) -> 0.371 | O31: =VLOOKUP(A31,[3]total_freq!$A:$F,6,0) -> #N/A | P31: =VLOOKUP(A31,[4]total_freq!$A:$F,6,0) -> 0.002 | Q31: =VLOOKUP(A31,[5]total_freq!$A:$F,6,0) -> #N/A | R31: =VLOOKUP(A31,[6]total_freq!$A:$F,6,0) -> 0.394 | S31: =VLOOKUP(A31,[7]total_freq!$A:$F,6,0) -> 0.66 | T31: =VLOOKUP(A31,[8]total_freq!$A:$F,6,0) -> #N/A | U31: =VLOOKUP(A31,[9]total_freq!$A:$F,6,0) -> 0.355 | V31: =VLOOKUP(A31,[10]total_freq!$A:$F,6,0) -> #N/A
A32: 家庭主妇 | B32: 9 | D32: =OR(E32,F32,G32>0.98,H32>0.98,I32) -> FALSE | E32: =IF(ISNA(VLOOKUP(A32,freq_country_woman!A:A:freq_country_woman!GP:GP,198,0)),FALSE,VLOOKUP(A32,freq_country_woman!A:A:freq_country_woman!GP:GP,198,0)) -> FALSE | F32: =IF(ISNA(VLOOKUP(A32,freq_country_man!A:A:freq_country_man!GP:GP,198,0)),FALSE,VLOOKUP(A32,freq_country_man!A:A:freq_country_man!GP:GP,198,0)) -> FALSE | G32: =IF(ISNA(VLOOKUP(A32,freq_country_woman!A:A:freq_country_woman!GQ:GQ,199,0)),0,VLOOKUP(A32,freq_country_woman!A:A:freq_country_woman!GQ:GQ,199,0)) -> 0.0051020408 | H32: =IF(ISNA(VLOOKUP(A32,freq_country_man!A:A:freq_country_man!GQ:GQ,199,0)),0,VLOOKUP(A32,freq_country_man!A:A:freq_country_man!GQ:GQ,199,0)) -> 0 | J32: =VLOOKUP(A32,'词频排序表（数据中间处理）'!A:C,3,0) -> 0.534 | K32: =VLOOKUP(A32,'词频排序表（数据中间处理）'!G:I,3,0) -> #N/A | L32: =IF(ISNA(J32),0,J32)-IF(ISNA(K32),0,K32) -> 0.534 | M32: =VLOOKUP(A32,[1]total_freq!$A:$F,6,0) -> 0.652 | N32: =VLOOKUP(A32,[2]total_freq!$A:$F,6,0) -> 0.002 | O32: =VLOOKUP(A32,[3]total_freq!$A:$F,6,0) -> #N/A | P32: =VLOOKUP(A32,[4]total_freq!$A:$F,6,0) -> 0.411 | Q32: =VLOOKUP(A32,[5]total_freq!$A:$F,6,0) -> #N/A | R32: =VLOOKUP(A32,[6]total_freq!$A:$F,6,0) -> 0.529 | S32: =VLOOKUP(A32,[7]total_freq!$A:$F,6,0) -> 0.522 | T32: =VLOOKUP(A32,[8]total_freq!$A:$F,6,0) -> 0.538 | U32: =VLOOKUP(A32,[9]total_freq!$A:$F,6,0) -> #N/A | V32: =VLOOKUP(A32,[10]total_freq!$A:$F,6,0) -> #N/A
A33: 子女 | B33: 8 | D33: =OR(E33,F33,G33>0.98,H33>0.98,I33) -> FALSE | E33: =IF(ISNA(VLOOKUP(A33,freq_country_woman!A:A:freq_country_woman!GP:GP,198,0)),FALSE,VLOOKUP(A33,freq_country_woman!A:A:freq_country_woman!GP:GP,198,0)) -> FALSE | F33: =IF(ISNA(VLOOKUP(A33,freq_country_man!A:A:freq_country_man!GP:GP,198,0)),FALSE,VLOOKUP(A33,freq_country_man!A:A:freq_country_man!GP:GP,198,0)) -> FALSE | G33: =IF(ISNA(VLOOKUP(A33,freq_country_woman!A:A:freq_country_woman!GQ:GQ,199,0)),0,VLOOKUP(A33,freq_country_woman!A:A:freq_country_woman!GQ:GQ,199,0)) -> 0.0051020408 | H33: =IF(ISNA(VLOOKUP(A33,freq_country_man!A:A:freq_country_man!GQ:GQ,199,0)),0,VLOOKUP(A33,freq_country_man!A:A:freq_country_man!GQ:GQ,199,0)) -> 0 | J33: =VLOOKUP(A33,'词频排序表（数据中间处理）'!A:C,3,0) -> 0.503 | K33: =VLOOKUP(A33,'词频排序表（数据中间处理）'!G:I,3,0) -> #N/A | L33: =IF(ISNA(J33),0,J33)-IF(ISNA(K33),0,K33) -> 0.503 | M33: =VLOOKUP(A33,[1]total_freq!$A:$F,6,0) -> 0.684 | N33: =VLOOKUP(A33,[2]total_freq!$A:$F,6,0) -> 0.426 | O33: =VLOOKUP(A33,[3]total_freq!$A:$F,6,0) -> #N/A | P33: =VLOOKUP(A33,[4]total_freq!$A:$F,6,0) -> #N/A | Q33: =VLOOKUP(A33,[5]total_freq!$A:$F,6,0) -> #N/A | R33: =VLOOKUP(A33,[6]total_freq!$A:$F,6,0) -> 0.602 | S33: =VLOOKUP(A33,[7]total_freq!$A:$F,6,0) -> 0.374 | T33: =VLOOKUP(A33,[8]total_freq!$A:$F,6,0) -> #N/A | U33: =VLOOKUP(A33,[9]total_freq!$A:$F,6,0) -> 0.002 | V33: =VLOOKUP(A33,[10]total_freq!$A:$F,6,0) -> 0.002
A34: 展现 | B34: 8 | D34: =OR(E34,F34,G34>0.98,H34>0.98,I34) -> FALSE | E34: =IF(ISNA(VLOOKUP(A34,freq_country_woman!A:A:freq_country_woman!GP:GP,198,0)),FALSE,VLOOKUP(A34,freq_country_woman!A:A:freq_country_woman!GP:GP,198,0)) -> FALSE | F34: =IF(ISNA(VLOOKUP(A34,freq_country_man!A:A:freq_country_man!GP:GP,198,0)),FALSE,VLOOKUP(A34,freq_country_man!A:A:freq_country_man!GP:GP,198,0)) -> FALSE | G34: =IF(ISNA(VLOOKUP(A34,freq_country_woman!A:A:freq_country_woman!GQ:GQ,199,0)),0,VLOOKUP(A34,freq_country_woman!A:A:freq_country_woman!GQ:GQ,199,0)) -> 0 | H34: =IF(ISNA(VLOOKUP(A34,freq_country_man!A:A:freq_country_man!GQ:GQ,199,0)),0,VLOOKUP(A34,freq_country_man!A:A:freq_country_man!GQ:GQ,199,0)) -> 0 | J34: =VLOOKUP(A34,'词频排序表（数据中间处理）'!A:C,3,0) -> 0.503 | K34: =VLOOKUP(A34,'词频排序表（数据中间处理）'!G:I,3,0) -> #N/A | L34: =IF(ISNA(J34),0,J34)-IF(ISNA(K34),0,K34) -> 0.503 | M34: =VLOOKUP(A34,[1]total_freq!$A:$F,6,0) -> 0.431 | N34: =VLOOKUP(A34,[2]total_freq!$A:$F,6,0) -> 0.002 | O34: =VLOOKUP(A34,[3]total_freq!$A:$F,6,0) -> 0.002 | P34: =VLOOKUP(A34,[4]total_freq!$A:$F,6,0) -> 0.411 | Q34: =VLOOKUP(A34,[5]total_freq!$A:$F,6,0) -> 0.409 | R34: =VLOOKUP(A34,[6]total_freq!$A:$F,6,0) -> 0.394 | S34: =VLOOKUP(A34,[7]total_freq!$A:$F,6,0) -> 0.374 | T34: =VLOOKUP(A34,[8]total_freq!$A:$F,6,0) -> 0.393 | U34: =VLOOKUP(A34,[9]total_freq!$A:$F,6,0) -> 0.002 | V34: =VLOOKUP(A34,[10]total_freq!$A:$F,6,0) -> 0.002
A35: 传统服装 | B35: 8 | D35: =OR(E35,F35,G35>0.98,H35>0.98,I35) -> FALSE | E35: =IF(ISNA(VLOOKUP(A35,freq_country_woman!A:A:freq_country_woman!GP:GP,198,0)),FALSE,VLOOKUP(A35,freq_country_woman!A:A:freq_country_woman!GP:GP,198,0)) -> FALSE | F35: =IF(ISNA(VLOOKUP(A35,freq_country_man!A:A:freq_country_man!GP:GP,198,0)),FALSE,VLOOKUP(A35,freq_country_man!A:A:freq_country_man!GP:GP,198,0)) -> FALSE | G35: =IF(ISNA(VLOOKUP(A35,freq_country_woman!A:A:freq_country_woman!GQ:GQ,199,0)),0,VLOOKUP(A35,freq_country_woman!A:A:freq_country_woman!GQ:GQ,199,0)) -> 0.0051020408 | H35: =IF(ISNA(VLOOKUP(A35,freq_country_man!A:A:freq_country_man!GQ:GQ,199,0)),0,VLOOKUP(A35,freq_country_man!A:A:freq_country_man!GQ:GQ,199,0)) -> 0 | J35: =VLOOKUP(A35,'词频排序表（数据中间处理）'!A:C,3,0) -> 0.503 | K35: =VLOOKUP(A35,'词频排序表（数据中间处理）'!G:I,3,0) -> #N/A | L35: =IF(ISNA(J35),0,J35)-IF(ISNA(K35),0,K35) -> 0.503 | M35: =VLOOKUP(A35,[1]total_freq!$A:$F,6,0) -> 0.738 | N35: =VLOOKUP(A35,[2]total_freq!$A:$F,6,0) -> #N/A | O35: =VLOOKUP(A35,[3]total_freq!$A:$F,6,0) -> #N/A | P35: =VLOOKUP(A35,[4]total_freq!$A:$F,6,0) -> #N/A | Q35: =VLOOKUP(A35,[5]total_freq!$A:$F,6,0) -> #N/A | R35: =VLOOKUP(A35,[6]total_freq!$A:$F,6,0) -> 0.529 | S35: =VLOOKUP(A35,[7]total_freq!$A:$F,6,0) -> 0.374 | T35: =VLOOKUP(A35,[8]total_freq!$A:$F,6,0) -> 0.002 | U35: =VLOOKUP(A35,[9]total_freq!$A:$F,6,0) -> #N/A | V35: =VLOOKUP(A35,[10]total_freq!$A:$F,6,0) -> 0.382
A36: 着装 | B36: 8 | D36: =OR(E36,F36,G36>0.98,H36>0.98,I36) -> FALSE | E36: =IF(ISNA(VLOOKUP(A36,freq_country_woman!A:A:freq_country_woman!GP:GP,198,0)),FALSE,VLOOKUP(A36,freq_country_woman!A:A:freq_country_woman!GP:GP,198,0)) -> FALSE | F36: =IF(ISNA(VLOOKUP(A36,freq_country_man!A:A:freq_country_man!GP:GP,198,0)),FALSE,VLOOKUP(A36,freq_country_man!A:A:freq_country_man!GP:GP,198,0)) -> FALSE | G36: =IF(ISNA(VLOOKUP(A36,freq_country_woman!A:A:freq_country_woman!GQ:GQ,199,0)),0,VLOOKUP(A36,freq_country_woman!A:A:freq_country_woman!GQ:GQ,199,0)) -> 0.0051020408 | H36: =IF(ISNA(VLOOKUP(A36,freq_country_man!A:A:freq_country_man!GQ:GQ,199,0)),0,VLOOKUP(A36,freq_country_man!A:A:freq_country_man!GQ:GQ,199,0)) -> 0 | J36: =VLOOKUP(A36,'词频排序表（数据中间处理）'!A:C,3,0) -> 0.503 | K36: =VLOOKUP(A36,'词频排序表（数据中间处理）'!G:I,3,0) -> #N/A | L36: =IF(ISNA(J36),0,J36)-IF(ISNA(K36),0,K36) -> 0.503 | M36: =VLOOKUP(A36,[1]total_freq!$A:$F,6,0) -> 0.684 | N36: =VLOOKUP(A36,[2]total_freq!$A:$F,6,0) -> 0.002 | O36: =VLOOKUP(A36,[3]total_freq!$A:$F,6,0) -> 0.002 | P36: =VLOOKUP(A36,[4]total_freq!$A:$F,6,0) -> #N/A | Q36: =VLOOKUP(A36,[5]total_freq!$A:$F,6,0) -> #N/A | R36: =VLOOKUP(A36,[6]total_freq!$A:$F,6,0) -> 0.002 | S36: =VLOOKUP(A36,[7]total_freq!$A:$F,6,0) -> 0.522 | T36: =VLOOKUP(A36,[8]total_freq!$A:$F,6,0) -> 0.002 | U36: =VLOOKUP(A36,[9]total_freq!$A:$F,6,0) -> 0.002 | V36: =VLOOKUP(A36,[10]total_freq!$A:$F,6,0) -> 0.382
A37: 多元化 | B37: 8 | D37: =OR(E37,F37,G37>0.98,H37>0.98,I37) -> FALSE | E37: =IF(ISNA(VLOOKUP(A37,freq_country_woman!A:A:freq_country_woman!GP:GP,198,0)),FALSE,VLOOKUP(A37,freq_country_woman!A:A:freq_country_woman!GP:GP,198,0)) -> FALSE | F37: =IF(ISNA(VLOOKUP(A37,freq_country_man!A:A:freq_country_man!GP:GP,198,0)),FALSE,VLOOKUP(A37,freq_country_man!A:A:freq_country_man!GP:GP,198,0)) -> FALSE | G37: =IF(ISNA(VLOOKUP(A37,freq_country_woman!A:A:freq_country_woman!GQ:GQ,199,0)),0,VLOOKUP(A37,freq_country_woman!A:A:freq_country_woman!GQ:GQ,199,0)) -> 0.0051020408 | H37: =IF(ISNA(VLOOKUP(A37,freq_country_man!A:A:freq_country_man!GQ:GQ,199,0)),0,VLOOKUP(A37,freq_country_man!A:A:freq_country_man!GQ:GQ,199,0)) -> 0 | J37: =VLOOKUP(A37,'词频排序表（数据中间处理）'!A:C,3,0) -> 0.503 | K37: =VLOOKUP(A37,'词频排序表（数据中间处理）'!G:I,3,0) -> #N/A | L37: =IF(ISNA(J37),0,J37)-IF(ISNA(K37),0,K37) -> 0.503 | M37: =VLOOKUP(A37,[1]total_freq!$A:$F,6,0) -> 0.002 | N37: =VLOOKUP(A37,[2]total_freq!$A:$F,6,0) -> #N/A | O37: =VLOOKUP(A37,[3]total_freq!$A:$F,6,0) -> 0.002 | P37: =VLOOKUP(A37,[4]total_freq!$A:$F,6,0) -> 0.644 | Q37: =VLOOKUP(A37,[5]total_freq!$A:$F,6,0) -> 0.002 | R37: =VLOOKUP(A37,[6]total_freq!$A:$F,6,0) -> #N/A | S37: =VLOOKUP(A37,[7]total_freq!$A:$F,6,0) -> #N/A | T37: =VLOOKUP(A37,[8]total_freq!$A:$F,6,0) -> 0.538 | U37: =VLOOKUP(A37,[9]total_freq!$A:$F,6,0) -> 0.374 | V37: =VLOOKUP(A37,[10]total_freq!$A:$F,6,0) -> 0.513
A38: 斯拉夫 | B38: 8 | D38: =OR(E38,F38,G38>0.98,H38>0.98,I38) -> FALSE | E38: =IF(ISNA(VLOOKUP(A38,freq_country_woman!A:A:freq_country_woman!GP:GP,198,0)),FALSE,VLOOKUP(A38,freq_country_woman!A:A:freq_country_woman!GP:GP,198,0)) -> FALSE | F38: =IF(ISNA(VLOOKUP(A38,freq_country_man!A:A:freq_country_man!GP:GP,198,0)),FALSE,VLOOKUP(A38,freq_country_man!A:A:freq_country_man!GP:GP,198,0)) -> FALSE | G38: =IF(ISNA(VLOOKUP(A38,freq_country_woman!A:A:freq_country_woman!GQ:GQ,199,0)),0,VLOOKUP(A38,freq_country_woman!A:A:freq_country_woman!GQ:GQ,199,0)) -> 0 | H38: =IF(ISNA(VLOOKUP(A38,freq_country_man!A:A:freq_country_man!GQ:GQ,199,0)),0,VLOOKUP(A38,freq_country_man!A:A:freq_country_man!GQ:GQ,199,0)) -> 0 | J38: =VLOOKUP(A38,'词频排序表（数据中间处理）'!A:C,3,0) -> 0.503 | K38: =VLOOKUP(A38,'词频排序表（数据中间处理）'!G:I,3,0) -> #N/A | L38: =IF(ISNA(J38),0,J38)-IF(ISNA(K38),0,K38) -> 0.503 | M38: =VLOOKUP(A38,[1]total_freq!$A:$F,6,0) -> #N/A | N38: =VLOOKUP(A38,[2]total_freq!$A:$F,6,0) -> 0.426 | O38: =VLOOKUP(A38,[3]total_freq!$A:$F,6,0) -> #N/A | P38: =VLOOKUP(A38,[4]total_freq!$A:$F,6,0) -> 0.582 | Q38: =VLOOKUP(A38,[5]total_freq!$A:$F,6,0) -> 0.53 | R38: =VLOOKUP(A38,[6]total_freq!$A:$F,6,0) -> #N/A | S38: =VLOOKUP(A38,[7]total_freq!$A:$F,6,0) -> #N/A | T38: =VLOOKUP(A38,[8]total_freq!$A:$F,6,0) -> 0.393 | U38: =VLOOKUP(A38,[9]total_freq!$A:$F,6,0) -> 0.652 | V38: =VLOOKUP(A38,[10]total_freq!$A:$F,6,0) -> #N/A
A39: 身材 | B39: 22 | C39: 4 | D39: =OR(E39,F39,G39>0.98,H39>0.98,I39) -> FALSE | E39: =IF(ISNA(VLOOKUP(A39,freq_country_woman!A:A:freq_country_woman!GP:GP,198,0)),FALSE,VLOOKUP(A39,freq_country_woman!A:A:freq_country_woman!GP:GP,198,0)) -> FALSE | F39: =IF(ISNA(VLOOKUP(A39,freq_country_man!A:A:freq_country_man!GP:GP,198,0)),FALSE,VLOOKUP(A39,freq_country_man!A:A:freq_country_man!GP:GP,198,0)) -> FALSE | G39: =IF(ISNA(VLOOKUP(A39,freq_country_woman!A:A:freq_country_woman!GQ:GQ,199,0)),0,VLOOKUP(A39,freq_country_woman!A:A:freq_country_woman!GQ:GQ,199,0)) -> 0.035714286 | H39: =IF(ISNA(VLOOKUP(A39,freq_country_man!A:A:freq_country_man!GQ:GQ,199,0)),0,VLOOKUP(A39,freq_country_man!A:A:freq_country_man!GQ:GQ,199,0)) -> 0.0051020408 | J39: =VLOOKUP(A39,'词频排序表（数据中间处理）'!A:C,3,0) -> 0.741 | K39: =VLOOKUP(A39,'词频排序表（数据中间处理）'!G:I,3,0) -> 0.261 | L39: =IF(ISNA(J39),0,J39)-IF(ISNA(K39),0,K39) -> 0.48 | M39: =VLOOKUP(A39,[1]total_freq!$A:$F,6,0) -> #N/A | N39: =VLOOKUP(A39,[2]total_freq!$A:$F,6,0) -> 0.315 | O39: =VLOOKUP(A39,[3]total_freq!$A:$F,6,0) -> 0.691 | P39: =VLOOKUP(A39,[4]total_freq!$A:$F,6,0) -> #N/A | Q39: =VLOOKUP(A39,[5]total_freq!$A:$F,6,0) -> 0.779 | R39: =VLOOKUP(A39,[6]total_freq!$A:$F,6,0) -> 0.529 | S39: =VLOOKUP(A39,[7]total_freq!$A:$F,6,0) -> 0.159 | T39: =VLOOKUP(A39,[8]total_freq!$A:$F,6,0) -> 0.002 | U39: =VLOOKUP(A39,[9]total_freq!$A:$F,6,0) -> 0.875 | V39: =VLOOKUP(A39,[10]total_freq!$A:$F,6,0) -> #N/A
A40: 眼睛 | B40: 13 | C40: 3 | D40: =OR(E40,F40,G40>0.98,H40>0.98,I40) -> FALSE | E40: =IF(ISNA(VLOOKUP(A40,freq_country_woman!A:A:freq_country_woman!GP:GP,198,0)),FALSE,VLOOKUP(A40,freq_country_woman!A:A:freq_country_woman!GP:GP,198,0)) -> FALSE | F40: =IF(ISNA(VLOOKUP(A40,freq_country_man!A:A:freq_country_man!GP:GP,198,0)),FALSE,VLOOKUP(A40,freq_country_man!A:A:freq_country_man!GP:GP,198,0)) -> FALSE | G40: =IF(ISNA(VLOOKUP(A40,freq_country_woman!A:A:freq_country_woman!GQ:GQ,199,0)),0,VLOOKUP(A40,freq_country_woman!A:A:freq_country_woman!GQ:GQ,199,0)) -> 0.015306122 | H40: =IF(ISNA(VLOOKUP(A40,freq_country_man!A:A:freq_country_man!GQ:GQ,199,0)),0,VLOOKUP(A40,freq_country_man!A:A:freq_country_man!GQ:GQ,199,0)) -> 0.0051020408 | J40: =VLOOKUP(A40,'词频排序表（数据中间处理）'!A:C,3,0) -> 0.626 | K40: =VLOOKUP(A40,'词频排序表（数据中间处理）'!G:I,3,0) -> 0.15 | L40: =IF(ISNA(J40),0,J40)-IF(ISNA(K40),0,K40) -> 0.476 | M40: =VLOOKUP(A40,[1]total_freq!$A:$F,6,0) -> #N/A | N40: =VLOOKUP(A40,[2]total_freq!$A:$F,6,0) -> 0.002 | O40: =VLOOKUP(A40,[3]total_freq!$A:$F,6,0) -> -0.025 | P40: =VLOOKUP(A40,[4]total_freq!$A:$F,6,0) -> 0.642 | Q40: =VLOOKUP(A40,[5]total_freq!$A:$F,6,0) -> 0.648 | R40: =VLOOKUP(A40,[6]total_freq!$A:$F,6,0) -> 0.394 | S40: =VLOOKUP(A40,[7]total_freq!$A:$F,6,0) -> -0.503 | T40: =VLOOKUP(A40,[8]total_freq!$A:$F,6,0) -> 0.645 | U40: =VLOOKUP(A40,[9]total_freq!$A:$F,6,0) -> 0.652 | V40: =VLOOKUP(A40,[10]total_freq!$A:$F,6,0) -> #N/A
...

Sheet 2. 女性共现表
A1: Edges | B1: Weight | C1: V1 | D1: V2 | E1: V1_deleted | F1: V2_deleted | G1: “温柔”“美丽”的她 | H1: “承担”“家务”的她 | I1: “遵守”“规范”的她
A2: ('女人', '通常') | B2: 1085 | C2: 女人 | D2: 通常 | E2: =VLOOKUP(C2,'1. 词频表'!A:D,4,0) -> TRUE | F2: =VLOOKUP(D2,'1. 词频表'!A:D,4,0) -> TRUE | G2: =(COUNTIF(Sheet1!A:A,$C2)+COUNTIF(Sheet1!A:A,$D2))>0 -> FALSE | H2: =(COUNTIF(Sheet1!B:B,$C2)+COUNTIF(Sheet1!B:B,$D2))>0 -> FALSE | I2: =(COUNTIF(Sheet1!C:C,$C2)+COUNTIF(Sheet1!C:C,$D2))>0 -> FALSE
A3: ('认为', '通常') | B3: 955 | C3: 认为 | D3: 通常 | E3: =VLOOKUP(C3,'1. 词频表'!A:D,4,0) -> TRUE | F3: =VLOOKUP(D3,'1. 词频表'!A:D,4,0) -> TRUE | G3: =(COUNTIF(Sheet1!A:A,C3)+COUNTIF(Sheet1!A:A,D3))>0 -> FALSE | H3: =(COUNTIF(Sheet1!B:B,$C3)+COUNTIF(Sheet1!B:B,$D3))>0 -> FALSE | I3: =(COUNTIF(Sheet1!C:C,$C3)+COUNTIF(Sheet1!C:C,$D3))>0 -> FALSE
A4: ('女人', '认为') | B4: 679 | C4: 女人 | D4: 认为 | E4: =VLOOKUP(C4,'1. 词频表'!A:D,4,0) -> TRUE | F4: =VLOOKUP(D4,'1. 词频表'!A:D,4,0) -> TRUE | G4: =(COUNTIF(Sheet1!A:A,C4)+COUNTIF(Sheet1!A:A,D4))>0 -> FALSE | H4: =(COUNTIF(Sheet1!B:B,$C4)+COUNTIF(Sheet1!B:B,$D4))>0 -> FALSE | I4: =(COUNTIF(Sheet1!C:C,$C4)+COUNTIF(Sheet1!C:C,$D4))>0 -> FALSE
A5: ('女性', '通常') | B5: 533 | C5: 女性 | D5: 通常 | E5: =VLOOKUP(C5,'1. 词频表'!A:D,4,0) -> FALSE | F5: =VLOOKUP(D5,'1. 词频表'!A:D,4,0) -> TRUE | G5: =(COUNTIF(Sheet1!A:A,C5)+COUNTIF(Sheet1!A:A,D5))>0 -> FALSE | H5: =(COUNTIF(Sheet1!B:B,$C5)+COUNTIF(Sheet1!B:B,$D5))>0 -> FALSE | I5: =(COUNTIF(Sheet1!C:C,$C5)+COUNTIF(Sheet1!C:C,$D5))>0 -> FALSE
A6: ('角色', '重要') | B6: 408 | C6: 角色 | D6: 重要 | E6: =VLOOKUP(C6,'1. 词频表'!A:D,4,0) -> FALSE | F6: =VLOOKUP(D6,'1. 词频表'!A:D,4,0) -> FALSE | G6: =(COUNTIF(Sheet1!A:A,C6)+COUNTIF(Sheet1!A:A,D6))>0 -> FALSE | H6: =(COUNTIF(Sheet1!B:B,$C6)+COUNTIF(Sheet1!B:B,$D6))>0 -> FALSE | I6: =(COUNTIF(Sheet1!C:C,$C6)+COUNTIF(Sheet1!C:C,$D6))>0 -> FALSE
A7: ('热情', '通常') | B7: 389 | C7: 热情 | D7: 通常 | E7: =VLOOKUP(C7,'1. 词频表'!A:D,4,0) -> FALSE | F7: =VLOOKUP(D7,'1. 词频表'!A:D,4,0) -> TRUE | G7: =(COUNTIF(Sheet1!A:A,C7)+COUNTIF(Sheet1!A:A,D7))>0 -> FALSE | H7: =(COUNTIF(Sheet1!B:B,$C7)+COUNTIF(Sheet1!B:B,$D7))>0 -> FALSE | I7: =(COUNTIF(Sheet1!C:C,$C7)+COUNTIF(Sheet1!C:C,$D7))>0 -> FALSE
A8: ('家庭', '角色') | B8: 367 | C8: 家庭 | D8: 角色 | E8: =VLOOKUP(C8,'1. 词频表'!A:D,4,0) -> FALSE | F8: =VLOOKUP(D8,'1. 词频表'!A:D,4,0) -> FALSE | G8: =(COUNTIF(Sheet1!A:A,C8)+COUNTIF(Sheet1!A:A,D8))>0 -> FALSE | H8: =(COUNTIF(Sheet1!B:B,$C8)+COUNTIF(Sheet1!B:B,$D8))>0 -> TRUE | I8: =(COUNTIF(Sheet1!C:C,$C8)+COUNTIF(Sheet1!C:C,$D8))>0 -> FALSE
A9: ('家庭', '社区') | B9: 364 | C9: 家庭 | D9: 社区 | E9: =VLOOKUP(C9,'1. 词频表'!A:D,4,0) -> FALSE | F9: =VLOOKUP(D9,'1. 词频表'!A:D,4,0) -> FALSE | G9: =(COUNTIF(Sheet1!A:A,C9)+COUNTIF(Sheet1!A:A,D9))>0 -> FALSE | H9: =(COUNTIF(Sheet1!B:B,$C9)+COUNTIF(Sheet1!B:B,$D9))>0 -> TRUE | I9: =(COUNTIF(Sheet1!C:C,$C9)+COUNTIF(Sheet1!C:C,$D9))>0 -> FALSE
A10: ('家庭', '重视') | B10: 356 | C10: 家庭 | D10: 重视 | E10: =VLOOKUP(C10,'1. 词频表'!A:D,4,0) -> FALSE | F10: =VLOOKUP(D10,'1. 词频表'!A:D,4,0) -> FALSE | G10: =(COUNTIF(Sheet1!A:A,C10)+COUNTIF(Sheet1!A:A,D10))>0 -> FALSE | H10: =(COUNTIF(Sheet1!B:B,$C10)+COUNTIF(Sheet1!B:B,$D10))>0 -> TRUE | I10: =(COUNTIF(Sheet1!C:C,$C10)+COUNTIF(Sheet1!C:C,$D10))>0 -> FALSE
A11: ('描述', '通常') | B11: 353 | C11: 描述 | D11: 通常 | E11: =VLOOKUP(C11,'1. 词频表'!A:D,4,0) -> FALSE | F11: =VLOOKUP(D11,'1. 词频表'!A:D,4,0) -> TRUE | G11: =(COUNTIF(Sheet1!A:A,C11)+COUNTIF(Sheet1!A:A,D11))>0 -> FALSE | H11: =(COUNTIF(Sheet1!B:B,$C11)+COUNTIF(Sheet1!B:B,$D11))>0 -> FALSE | I11: =(COUNTIF(Sheet1!C:C,$C11)+COUNTIF(Sheet1!C:C,$D11))>0 -> FALSE
A12: ('家庭', '重要') | B12: 348 | C12: 家庭 | D12: 重要 | E12: =VLOOKUP(C12,'1. 词频表'!A:D,4,0) -> FALSE | F12: =VLOOKUP(D12,'1. 词频表'!A:D,4,0) -> FALSE | G12: =(COUNTIF(Sheet1!A:A,C12)+COUNTIF(Sheet1!A:A,D12))>0 -> FALSE | H12: =(COUNTIF(Sheet1!B:B,$C12)+COUNTIF(Sheet1!B:B,$D12))>0 -> TRUE | I12: =(COUNTIF(Sheet1!C:C,$C12)+COUNTIF(Sheet1!C:C,$D12))>0 -> FALSE
A13: ('家庭', '强烈') | B13: 328 | C13: 家庭 | D13: 强烈 | E13: =VLOOKUP(C13,'1. 词频表'!A:D,4,0) -> FALSE | F13: =VLOOKUP(D13,'1. 词频表'!A:D,4,0) -> FALSE | G13: =(COUNTIF(Sheet1!A:A,C13)+COUNTIF(Sheet1!A:A,D13))>0 -> FALSE | H13: =(COUNTIF(Sheet1!B:B,$C13)+COUNTIF(Sheet1!B:B,$D13))>0 -> TRUE | I13: =(COUNTIF(Sheet1!C:C,$C13)+COUNTIF(Sheet1!C:C,$D13))>0 -> FALSE
A14: ('女人', '热情') | B14: 326 | C14: 女人 | D14: 热情 | E14: =VLOOKUP(C14,'1. 词频表'!A:D,4,0) -> TRUE | F14: =VLOOKUP(D14,'1. 词频表'!A:D,4,0) -> FALSE | G14: =(COUNTIF(Sheet1!A:A,C14)+COUNTIF(Sheet1!A:A,D14))>0 -> FALSE | H14: =(COUNTIF(Sheet1!B:B,$C14)+COUNTIF(Sheet1!B:B,$D14))>0 -> FALSE | I14: =(COUNTIF(Sheet1!C:C,$C14)+COUNTIF(Sheet1!C:C,$D14))>0 -> FALSE
... A1664: ('中国', '女性') | B1664: 5 | C1664: 中国 | D1664: 女性 | E1664: =VLOOKUP(C1664,'1. 词频表'!A:D,4,0) -> FALSE | F1664: =VLOOKUP(D1664,'1. 词频表'!A:D,4,0) -> FALSE | G1664: =(COUNTIF(Sheet1!A:A,C1664)+COUNTIF(Sheet1!A:A,D1664))>0 -> FALSE | H1664: =(COUNTIF(Sheet1!B:B,$C1664)+COUNTIF(Sheet1!B:B,$D1664))>0 -> FALSE | I1664: =(COUNTIF(Sheet1!C:C,$C1664)+COUNTIF(Sheet1!C:C,$D1664))>0 -> FALSE

Sheet 3. 男性共现表
A1: Edges | B1: Weight | C1: V1 | D1: V2 | E1: V1_deleted | F1: V2_deleted | G1: “温柔”“美丽”的她 | H1: “承担”“家务”的她 | I1: “遵守”“规范”的她
